Workbook

Sheet Cover

Sheet Summary
A1: Midea
B2: 结果汇总 Summary | G2: 基本情景
B3: （特殊说明除外，单位为百万元人民币） | C3: 43100 | D3: 44561 | E3: 44926 | F3: 45291 | G3: 45657 | H3: 46022 | I3: 46387 | J3: 46752 | K3: 47118
A5: 基本说明
B6: 公司代码 | C6: 000333.SZ
B7: 公司简称 | C7: 美的集团
A9: 估值参数及结果 | C9: 下限
B10: Wacc | C10: =FCFF估值!C82 -> 0.080252681
B11: 长期增长率（g） | C11: =FCFF估值!Q36 -> 0.02
B12: 股价（元/股） | C12: 88.8
A14: 关键财务数据及比率
B15: 营业收入 | D15: =收入拆分!C4 -> 312259.83 | E15: =收入拆分!D4 -> 320233.61 | F15: =收入拆分!E4 -> 348772.97 | G15: =收入拆分!F4 -> 365795.06 | H15: =收入拆分!G4 -> 386400.84 | I15: =收入拆分!H4 -> 411412.62 | J15: =收入拆分!I4 -> 441862.5 | K15: =收入拆分!J4 -> 479049.32
B16: 智能家居业务 | D16: =收入拆分!C10 -> 234918 | E16: =收入拆分!D10 -> 232825 | F16: =收入拆分!E10 -> 246351 | G16: =收入拆分!F10 -> 246351 | H16: =收入拆分!G10 -> 246351 | I16: =收入拆分!H10 -> 246351 | J16: =收入拆分!I10 -> 246351 | K16: =收入拆分!J10 -> 246351
B17: 工商业解决方案 | D17: =收入拆分!C16 -> 73379 | E17: =收入拆分!D16 -> 83639 | F17: =收入拆分!E16 -> 97781 | G17: =收入拆分!F16 -> 114803.09 | H17: =收入拆分!G16 -> 135362.46 | I17: =收入拆分!H16 -> 160280.5 | J17: =收入拆分!I16 -> 190586.94 | K17: =收入拆分!J16 -> 227576.78
B18: 其他 | D18: =收入拆分!C22 -> 3962.8344 | E18: =收入拆分!D22 -> 3769.6083 | F18: =收入拆分!E22 -> 4640.9686 | G18: =收入拆分!F22 -> 4640.9686 | H18: =收入拆分!G22 -> 4687.3782 | I18: =收入拆分!H22 -> 4781.1258 | J18: =收入拆分!I22 -> 4924.5596 | K18: =收入拆分!J22 -> 5121.542
B20: YOY 增长率
B21: 营业收入 | D21: -- | E21: =收入拆分!D5 -> 0.025535702 | F21: =收入拆分!E5 -> 0.089120441 | G21: =收入拆分!F5 -> 0.04880564 | H21: =收入拆分!G5 -> 0.056331497 | I21: =收入拆分!H5 -> 0.064730149 | J21: =收入拆分!I5 -> 0.074012993 | K21: =收入拆分!J5 -> 0.084159259
B22: 智能家居业务 | D22: -- | E22: =收入拆分!D11 -> -0.0089094918 | F22: =收入拆分!E11 -> 0.024044943 | G22: =收入拆分!F11 -> 0 | H22: =收入拆分!G11 -> 0 | I22: =收入拆分!H11 -> 0 | J22: =收入拆分!I11 -> 0 | K22: =收入拆分!J11 -> 0
B23: 工商业解决方案 | D23: -- | E23: =收入拆分!D17 -> 0.13982202 | F23: =收入拆分!E17 -> 0.1690838 | G23: =收入拆分!F17 -> 0.1740838 | H23: =收入拆分!G17 -> 0.1790838 | I23: =收入拆分!H17 -> 0.1840838 | J23: =收入拆分!I17 -> 0.1890838 | K23: =收入拆分!J17 -> 0.1940838
B24: 其他 | D24: -- | E24: =收入拆分!D23 -> -0.048759562 | F24: =收入拆分!E23 -> 0.23115406 | G24: =收入拆分!F23 -> 0 | H24: =收入拆分!G23 -> 0.01 | I24: =收入拆分!H23 -> 0.02 | J24: =收入拆分!I23 -> 0.03 | K24: =收入拆分!J23 -> 0.04
B26: 营业成本 | D26: =-收入拆分!C6 -> 237288.37 | E26: =-收入拆分!D6 -> 239558.12 | F26: =-收入拆分!E6 -> 252116.51 | G26: =-收入拆分!F6 -> 264275.95 | H26: =-收入拆分!G6 -> 279503 | I26: =-收入拆分!H6 -> 297878.42 | J26: =-收入拆分!I6 -> 320117.96 | K26: =-收入拆分!J6 -> 347117.3
B28: 毛利率（Gross margin) | D28: =收入拆分!C7 -> 0.2400932 | E28: =收入拆分!D7 -> 0.25192699 | F28: =收入拆分!E7 -> 0.27713289 | G28: =收入拆分!F7 -> 0.27753001 | H28: =收入拆分!G7 -> 0.27665013 | I28: =收入拆分!H7 -> 0.2759619 | J28: =收入拆分!I7 -> 0.27552585 | K28: =收入拆分!J7 -> 0.27540383
B29: 智能家居业务 | D29: =收入拆分!C13 -> 0.251 | E29: =收入拆分!D13 -> 0.27 | F29: =收入拆分!E13 -> 0.298 | G29: =收入拆分!F13 -> 0.3 | H29: =收入拆分!G13 -> 0.3 | I29: =收入拆分!H13 -> 0.3 | J29: =收入拆分!I13 -> 0.3 | K29: =收入拆分!J13 -> 0.3
B30: 工商业解决方案 | D30: =收入拆分!C19 -> 0.196 | E30: =收入拆分!D19 -> 0.199 | F30: =收入拆分!E19 -> 0.223 | G30: =收入拆分!F19 -> 0.228 | H30: =收入拆分!G19 -> 0.233 | I30: =收入拆分!H19 -> 0.238 | J30: =收入拆分!I19 -> 0.243 | K30: =收入拆分!J19 -> 0.248
B31: 其他 | D31: =收入拆分!C25 -> 0.41 | E31: =收入拆分!D25 -> 0.31 | F31: =收入拆分!E25 -> 0.31 | G31: =收入拆分!F25 -> 0.31 | H31: =收入拆分!G25 -> 0.31 | I31: =收入拆分!H25 -> 0.31 | J31: =收入拆分!I25 -> 0.31 | K31: =收入拆分!J25 -> 0.31
B33: 销售费用 | D33: =-IS!C7 -> 28647.34 | E33: =-IS!D7 -> 28716.12 | F33: =-IS!E7 -> 34880.88 | G33: =-IS!F7 -> 36975.213 | H33: =-IS!G7 -> 39472.11 | I33: =-IS!H7 -> 42467.973 | J33: =-IS!I7 -> 46084.61 | K33: =-IS!J7 -> 50476.358
B34: 销售费用率 | D34: =Assumptions!C16 -> 0.083432173 | E34: =Assumptions!D16 -> 0.083064497 | F34: =Assumptions!E16 -> 0.093336808 | G34: =Assumptions!F16 -> 0.094336808 | H34: =Assumptions!G16 -> 0.095336808 | I34: =Assumptions!H16 -> 0.096336808 | J34: =Assumptions!I16 -> 0.097336808 | K34: =Assumptions!J16 -> 0.098336808
B36: 管理费用 | D36: =-IS!C8 -> 10266.28 | E36: =-IS!D8 -> 11582.66 | F36: =-IS!E8 -> 13476.91 | G36: =-IS!F8 -> 13742.71 | H36: =-IS!G8 -> 14516.858 | I36: =-IS!H8 -> 15456.536 | J36: =-IS!I8 -> 16600.521 | K36: =-IS!J8 -> 17997.608
B37: 管理费用率 | D37: =Assumptions!C17 -> 0.029899392 | E37: =Assumptions!D17 -> 0.033504102 | F37: =Assumptions!E17 -> 0.036062501 | G37: =Assumptions!F17 -> 0.035062501 | H37: =Assumptions!G17 -> 0.035062501 | I37: =Assumptions!H17 -> 0.035062501 | J37: =Assumptions!I17 -> 0.035062501 | K37: =Assumptions!J17 -> 0.035062501
B39: 研发费用 | D39: =-IS!C9 -> 12014.91 | E39: =-IS!D9 -> 12618.51 | F39: =-IS!E9 -> 14583.31 | G39: =-IS!F9 -> 15295.058 | H39: =-IS!G9 -> 16156.651 | I39: =-IS!H9 -> 17202.474 | J39: =-IS!I9 -> 18475.68 | K39: =-IS!J9 -> 20030.58
B40: 研发费用率 | D40: =Assumptions!C18 -> 0.034992081 | E40: =Assumptions!D18 -> 0.036500411 | F40: =Assumptions!E18 -> 0.039023087 | G40: =Assumptions!F18 -> 0.039023087 | H40: =Assumptions!G18 -> 0.039023087 | I40: =Assumptions!H18 -> 0.039023087 | J40: =Assumptions!I18 -> 0.039023087 | K40: =Assumptions!J18 -> 0.039023087
B42: 经营利润（EBIT) | D42: =IS!C10 -> 26296.92 | E42: =IS!D10 -> 30686.84 | F42: =IS!E10 -> 35470.83 | G42: =IS!F10 -> 40859.457 | H42: =IS!G10 -> 42382.808 | I42: =IS!H10 -> 44382.035 | J42: =IS!I10 -> 46986.978 | K42: =IS!J10 -> 50365.436
B43: 经营利润率（EBIT margin） | D43: =D42/D15 -> 0.084214866 | E43: =E42/E15 -> 0.095826419 | F43: =F42/F15 -> 0.10170178 | G43: =G42/G15 -> 0.11170041 | H43: =H42/H15 -> 0.10968612 | I43: =I42/I15 -> 0.10787718 | J43: =J42/J15 -> 0.10633846 | K43: =K42/K15 -> 0.10513622
B45: 所得税率 | D45: =Assumptions!C20 -> 0.13904497 | E45: =Assumptions!D20 -> 0.14696508 | F45: =Assumptions!E20 -> 0.16202984 | G45: =Assumptions!F20 -> 0.16202984 | H45: =Assumptions!G20 -> 0.16202984 | I45: =Assumptions!H20 -> 0.16202984 | J45: =Assumptions!I20 -> 0.16202984 | K45: =Assumptions!J20 -> 0.16202984
B46: EBIAT，NOPLAT | D46: =D42*(1-D45) -> 22640.466 | E46: =E42*(1-E45) -> 26176.946 | F46: =F42*(1-F45) -> 29723.497 | G46: =G42*(1-G45) -> 34239.006 | H46: =H42*(1-H45) -> 35515.529 | I46: =I42*(1-I45) -> 37190.821 | J46: =J42*(1-J45) -> 39373.685 | K46: =K42*(1-K45) -> 42204.732
B47: EBIAT margin | D47: =D46/D15 -> 0.072505212 | E47: =E46/E15 -> 0.081743282 | F47: =F46/F15 -> 0.085223053 | G47: =G46/G15 -> 0.09360161 | H47: =H46/H15 -> 0.091913695 | I47: =I46/I15 -> 0.09039786 | J47: =J46/J15 -> 0.089108456 | K47: =K46/K15 -> 0.088101017
B49: 归母净利润 | D49: =IS!C26 -> 28673.72 | E49: =IS!D26 -> 29610.66 | F49: =IS!E26 -> 33755.16 | G49: =IS!F26 -> 35022.043 | H49: =IS!G26 -> 36497.628 | I49: =IS!H26 -> 38358.315 | J49: =IS!I26 -> 40745.907 | K49: =IS!J26 -> 43805.251
B50: 归母净利润率 | D50: =D49/D15 -> 0.091826475 | E50: =E49/E15 -> 0.09246581 | F50: =F49/F15 -> 0.096782615 | G50: =G49/G15 -> 0.095742254 | H50: =H49/H15 -> 0.094455355 | I50: =I49/I15 -> 0.093235629 | J50: =J49/J15 -> 0.092213996 | K50: =K49/K15 -> 0.091442048
B52: 经营性营运资金（OWC） | D52: =OWC!D26 -> -4298.46 | E52: =OWC!E26 -> -43994.11 | F52: =OWC!F26 -> -48294.73 | G52: =OWC!G26 -> -50602.922 | H52: =OWC!H26 -> -53386.298 | I52: =OWC!I26 -> -56752.457 | J52: =OWC!J26 -> -60835.939 | K52: =OWC!K26 -> 0
B53: OWC/营业收入 | D53: =D52/D15 -> -0.013765651 | E53: =E52/E15 -> -0.1373813 | F53: =F52/F15 -> -0.13847039 | G53: =G52/G15 -> -0.13833681 | H53: =H52/H15 -> -0.138163 | I53: =I52/I15 -> -0.13794535 | J53: =J52/J15 -> -0.1376807 | K53: =K52/K15 -> 0
...

Sheet IS
B2: 单位：百万元 | C2: =Assumptions!C2 -> 2021 | D2: =Assumptions!D2 -> 2022 | E2: =Assumptions!E2 -> 2023 | F2: =Assumptions!F2 -> 2024 | G2: =Assumptions!G2 -> 2025 | H2: =Assumptions!H2 -> 2026 | I2: =Assumptions!I2 -> 2027 | J2: =Assumptions!J2 -> 2028 | L2: 模型备注
B4: 营业总收入 | C4: 343360.83 | D4: 345708.71 | E4: 373709.8 | F4: =Assumptions!F9 -> 391948.95 | G4: =Assumptions!G9 -> 414028.02 | H4: =Assumptions!H9 -> 440828.11 | I4: =Assumptions!I9 -> 473455.12 | J4: =Assumptions!J9 -> 513300.75
B5: 营业成本 | C5: -264526 | D5: -260538.7 | E5: -273481.37 | F5: =-F4*(1-Assumptions!F14) -> -283171.35 | G5: =-G4*(1-Assumptions!G14) -> -299487.11 | H5: =-H4*(1-Assumptions!H14) -> -319176.35 | I5: =-I4*(1-Assumptions!I14) -> -343006 | J5: =-J4*(1-Assumptions!J14) -> -371935.76
B6: 税金及附加 | C6: -1609.38 | D6: -1565.88 | E6: -1816.5 | F6: =-F4*Assumptions!F15 -> -1905.1554 | G6: =-G4*Assumptions!G15 -> -2012.4757 | H6: =-H4*Assumptions!H15 -> -2142.7436 | I6: =-I4*Assumptions!I15 -> -2301.3344 | J6: =-J4*Assumptions!J15 -> -2495.013
B7: 销售费用 | C7: -28647.34 | D7: -28716.12 | E7: -34880.88 | F7: =-F4*Assumptions!F16 -> -36975.213 | G7: =-G4*Assumptions!G16 -> -39472.11 | H7: =-H4*Assumptions!H16 -> -42467.973 | I7: =-I4*Assumptions!I16 -> -46084.61 | J7: =-J4*Assumptions!J16 -> -50476.358
B8: 管理费用 | C8: -10266.28 | D8: -11582.66 | E8: -13476.91 | F8: =-F4*Assumptions!F17 -> -13742.71 | G8: =-G4*Assumptions!G17 -> -14516.858 | H8: =-H4*Assumptions!H17 -> -15456.536 | I8: =-I4*Assumptions!I17 -> -16600.521 | J8: =-J4*Assumptions!J17 -> -17997.608
B9: 研发费用 | C9: -12014.91 | D9: -12618.51 | E9: -14583.31 | F9: =-F4*Assumptions!F18 -> -15295.058 | G9: =-G4*Assumptions!G18 -> -16156.651 | H9: =-H4*Assumptions!H18 -> -17202.474 | I9: =-I4*Assumptions!I18 -> -18475.68 | J9: =-J4*Assumptions!J18 -> -20030.58
B10: EBIT | C10: =SUM(C4:C9) -> 26296.92 | D10: =SUM(D4:D9) -> 30686.84 | E10: =SUM(E4:E9) -> 35470.83 | F10: =SUM(F4:F9) -> 40859.457 | G10: =SUM(G4:G9) -> 42382.808 | H10: =SUM(H4:H9) -> 44382.035 | I10: =SUM(I4:I9) -> 46986.978 | J10: =SUM(J4:J9) -> 50365.436
B11: 财务费用 | C11: 4386.11 | D11: 3387.49 | E11: 3261.66 | F11: =Assumptions!F84 -> -918.15247 | G11: =Assumptions!G84 -> -678.80716 | H11: =Assumptions!H84 -> -455.38935 | I11: =Assumptions!I84 -> -208.4273 | J11: =Assumptions!J84 -> 67.247942
B12: 非经常性/非经营性损益 | C12: =SUM(C13:C21) -> 3134.59 | D12: =SUM(D13:D21) -> 938.75 | E12: =SUM(E13:E21) -> 1579.9 | F12: =AVERAGE(C12:E12) -> 1884.4133 | G12: =F12 -> 1884.4133 | H12: =G12 -> 1884.4133 | I12: =H12 -> 1884.4133 | J12: =I12 -> 1884.4133 | L12: 公司非经常性损益有一定波动，假定维持历史平均水平
B13: 其他收益 | C13: 1307.5 | D13: 1896.11 | E13: 2082.38
B14: 投资收益 | C14: 2365.77 | D14: 208.05 | E14: 463.56
B15: 净敞口套期收益 | C15: 0 | D15: 0 | E15: 0
B16: 公允价值变动收益 | C16: -166.41 | D16: -251.17 | E16: -226.49
B17: 信用减值损失 | C17: -383.45 | D17: -513.69 | E17: -198.62
B18: 资产减值损失 | C18: -483.42 | D18: -533.36 | E18: -439.78
B19: 资产处置收益 | C19: 58.26 | D19: -59.85 | E19: -60.87
B20: 营业外收入 | C20: 624.74 | D20: 395.41 | E20: 453.4
B21: 营业外支出 | C21: -188.4 | D21: -202.75 | E21: -493.68
B22: 税前利润 | C22: =SUM(C10:C12) -> 33817.62 | D22: =SUM(D10:D12) -> 35013.08 | E22: =SUM(E10:E12) -> 40312.39 | F22: =SUM(F10:F12) -> 41825.718 | G22: =SUM(G10:G12) -> 43588.415 | H22: =SUM(H10:H12) -> 45811.059 | I22: =SUM(I10:I12) -> 48662.964 | J22: =SUM(J10:J12) -> 52317.097
B23: 所得税费用 | C23: -4702.17 | D23: -5145.7 | E23: -6531.81 | F23: =-F22*Assumptions!F20 -> -6777.0143 | G23: =-G22*Assumptions!G20 -> -7062.6237 | H23: =-H22*Assumptions!H20 -> -7422.7584 | I23: =-I22*Assumptions!I20 -> -7884.8521 | J23: =-J22*Assumptions!J20 -> -8476.9307
B24: 净利润 | C24: =C22+C23 -> 29115.45 | D24: =D22+D23 -> 29867.38 | E24: =E22+E23 -> 33780.58 | F24: =F22+F23 -> 35048.704 | G24: =G22+G23 -> 36525.791 | H24: =H22+H23 -> 38388.3 | I24: =I22+I23 -> 40778.112 | J24: =J22+J23 -> 43840.166
B25: 少数股东损益 | C25: 441.73 | D25: 256.72 | E25: 25.42 | F25: =F4*Assumptions!F24 -> 26.660639 | G25: =G4*Assumptions!G24 -> 28.162473 | H25: =H4*Assumptions!H24 -> 29.985434 | I25: =I4*Assumptions!I24 -> 32.204746 | J25: =J4*Assumptions!J24 -> 34.915073
B26: 归属于母公司所有者的净利润 | C26: =C24-C25 -> 28673.72 | D26: =D24-D25 -> 29610.66 | E26: =E24-E25 -> 33755.16 | F26: =F24-F25 -> 35022.043 | G26: =G24-G25 -> 36497.628 | H26: =H24-H25 -> 38358.315 | I26: =I24-I25 -> 40745.907 | J26: =J24-J25 -> 43805.251
B27: 向母公司股东的分红 | C27: -11678 | D27: -17189 | E27: -20780 | F27: =F26*Assumptions!F23 -> -14263.494 | G27: =G26*Assumptions!G23 -> -14864.458 | H27: =H26*Assumptions!H23 -> -15622.263 | I27: =I26*Assumptions!I23 -> -16594.662 | J27: =J26*Assumptions!J23 -> -17840.647
B29: EBIT | D29: =D10 -> 30686.84 | E29: =E10 -> 35470.83 | F29: =F10 -> 40859.457 | G29: =G10 -> 42382.808 | H29: =H10 -> 44382.035 | I29: =I10 -> 46986.978 | J29: =J10 -> 50365.436
B30: 折旧摊销 | E30: 7348.92 | F30: =-DA!F10 -> 209.30383 | G30: =-DA!G10 -> 226.6201 | H30: =-DA!H10 -> 245.05725 | I30: =-DA!I10 -> 264.85898 | J30: =-DA!J10 -> 286.32722
B31: EBITDA | D31: =D29+D30 -> 30686.84 | E31: =E29+E30 -> 42819.75 | F31: =F29+F30 -> 41068.761 | G31: =G29+G30 -> 42609.428 | H31: =H29+H30 -> 44627.092 | I31: =I29+I30 -> 47251.837 | J31: =J29+J30 -> 50651.763
E32: =(E29-D29)/D29 -> 0.15589712 | F32: =(F29-E29)/E29 -> 0.15191715 | G32: =(G29-F29)/F29 -> 0.037282705 | H32: =(H29-G29)/G29 -> 0.04717069
E33: =E29/E4 -> 0.09491544 | F33: =F29/F4 -> 0.10424689 | G33: =G29/G4 -> 0.10236701 | H33: =H29/H4 -> 0.10067878

Sheet BS
L1: 模型备注
B2: 单位：百万元 | C2: =Assumptions!C2 -> 2021 | D2: =Assumptions!D2 -> 2022 | E2: =Assumptions!E2 -> 2023 | F2: =Assumptions!F2 -> 2024 | G2: =Assumptions!G2 -> 2025 | H2: =Assumptions!H2 -> 2026 | I2: =Assumptions!I2 -> 2027 | J2: =Assumptions!J2 -> 2028
B4: 流动资产：
B5: 货币资金 | C5: 71875.56 | D5: 55270.1 | E5: 81673.85 | F5: =CF!F76 -> 101353.34 | G5: =CF!G76 -> 117132.41 | H5: =CF!H76 -> 134452.28 | I5: =CF!I76 -> 153719.38 | J5: =CF!J76 -> 175293.05
B6: 交易性金融资产 | C6: 5879.2 | D6: 3284.59 | E6: 1790.59 | F6: =E6 -> 1790.59 | G6: =F6 -> 1790.59 | H6: =G6 -> 1790.59 | I6: =H6 -> 1790.59 | J6: =I6 -> 1790.59 | L6: 按上一年度
B7: 衍生金融资产 | C7: 545.87 | D7: 665.48 | E7: 1278.16 | F7: =E7 -> 1278.16 | G7: =F7 -> 1278.16 | H7: =G7 -> 1278.16 | I7: =H7 -> 1278.16 | J7: =I7 -> 1278.16
B8: 应收票据 | C8: 4784.91 | D8: 4758.13 | E8: 5521.96 | F8: =Assumptions!F29*Assumptions!F31 -> 5791.4628 | G8: =Assumptions!G29*Assumptions!G31 -> 6117.7046 | H8: =Assumptions!H29*Assumptions!H31 -> 6513.7045 | I8: =Assumptions!I29*Assumptions!I31 -> 6995.8033 | J8: =Assumptions!J29*Assumptions!J31 -> 7584.5649
B9: 应收账款 | C9: 24636.44 | D9: 28237.97 | E9: 32884.74 | F9: =Assumptions!F29*Assumptions!F32 -> 34489.701 | G9: =Assumptions!G29*Assumptions!G32 -> 36432.557 | H9: =Assumptions!H29*Assumptions!H32 -> 38790.842 | I9: =Assumptions!I29*Assumptions!I32 -> 41661.868 | J9: =Assumptions!J29*Assumptions!J32 -> 45168.1
B10: 应收款项融资 | C10: 10273.55 | D10: 13526.54 | E10: 13330.01 | F10: =Assumptions!F29*Assumptions!F33 -> 13980.59 | G10: =Assumptions!G29*Assumptions!G33 -> 14768.137 | H10: =Assumptions!H29*Assumptions!H33 -> 15724.081 | I10: =Assumptions!I29*Assumptions!I33 -> 16887.867 | J10: =Assumptions!J29*Assumptions!J33 -> 18309.138
B11: 预付款项 | C11: 4352.81 | D11: 4367.21 | E11: 3316.19 | F11: =-Assumptions!F34*IS!F5 -> 3433.6891 | G11: =-Assumptions!G34*IS!G5 -> 3631.5314 | H11: =-Assumptions!H34*IS!H5 -> 3870.2798 | I11: =-Assumptions!I34*IS!I5 -> 4159.2342 | J11: =-Assumptions!J34*IS!J5 -> 4510.0317
B12: 其他应收款 | C12: 3104.07 | D12: 2211.18 | E12: 2181.88 | F12: =AVERAGE(C12:E12) -> 2499.0433 | G12: =F12 -> 2499.0433 | H12: =G12 -> 2499.0433 | I12: =H12 -> 2499.0433 | J12: =I12 -> 2499.0433 | L12: 变化不大，按前三年均值
B13: 存货 | C13: 45924.44 | D13: 46044.9 | E13: 47339.26 | F13: =IFERROR(-IS!F5/(365/Assumptions!F35),0) -> 49016.583 | G13: =IFERROR(-IS!G5/(365/Assumptions!G35),0) -> 51840.82 | H13: =IFERROR(-IS!H5/(365/Assumptions!H35),0) -> 55249 | I13: =IFERROR(-IS!I5/(365/Assumptions!I35),0) -> 59373.88 | J13: =IFERROR(-IS!J5/(365/Assumptions!J35),0) -> 64381.583
B14: 合同资产 | C14: 3823.48 | D14: 4498.96 | E14: 4045.93 | F14: =Assumptions!F36*IS!F4 -> 4243.3942 | G14: =Assumptions!G36*IS!G4 -> 4482.431 | H14: =Assumptions!H36*IS!H4 -> 4772.5794 | I14: =Assumptions!I36*IS!I4 -> 5125.8123 | J14: =Assumptions!J36*IS!J4 -> 5557.1968
B15: 持有待售资产 | C15: 0 | D15: 0 | E15: 0 | F15: =AVERAGE(C15:E15) -> 0 | G15: =F15 -> 0 | H15: =G15 -> 0 | I15: =H15 -> 0 | J15: =I15 -> 0
B16: 一年内到期的非流动资产 | C16: 19851.58 | D16: 37553.08 | E16: 10760.58 | F16: =AVERAGE(C16:E16) -> 22721.747 | G16: =F16 -> 22721.747 | H16: =G16 -> 22721.747 | I16: =H16 -> 22721.747 | J16: =I16 -> 22721.747
B17: 其他流动资产 | C17: 33156.01 | D17: 46542.38 | E17: 62900.89 | F17: =AVERAGE(C17:E17) -> 47533.093 | G17: =F17 -> 47533.093 | H17: =G17 -> 47533.093 | I17: =H17 -> 47533.093 | J17: =I17 -> 47533.093 | L17: 按前三年均值
B18: 流动资产差额(特殊报表科目) | C18: 20656.6 | D18: 14138.76 | E18: 14296.96 | F18: =E18 -> 14296.96 | G18: =F18 -> 14296.96 | H18: =G18 -> 14296.96 | I18: =H18 -> 14296.96 | J18: =I18 -> 14296.96
B19: 流动资产合计 | C19: =SUM(C5:C18) -> 248864.52 | D19: =SUM(D5:D18) -> 261099.28 | E19: =SUM(E5:E18) -> 281321 | F19: =SUM(F5:F18) -> 302428.35 | G19: =SUM(G5:G18) -> 324525.19 | H19: =SUM(H5:H18) -> 349492.36 | I19: =SUM(I5:I18) -> 378043.44 | J19: =SUM(J5:J18) -> 410923.26
B21: 非流动资产：
B22: 以公允价值计量且其变动计入其他综合收益的金融资产 | C22: 0 | D22: 0 | E22: 0 | F22: =E22 -> 0 | G22: =F22 -> 0 | H22: =G22 -> 0 | I22: =H22 -> 0 | J22: =I22 -> 0
B23: 以摊余成本计量的金融资产 | C23: 0 | D23: 0 | E23: 0 | F23: =E23 -> 0 | G23: =F23 -> 0 | H23: =G23 -> 0 | I23: =H23 -> 0 | J23: =I23 -> 0
B24: 可供出售金融资产 | C24: 0 | D24: 0 | E24: 0 | F24: =E24 -> 0 | G24: =F24 -> 0 | H24: =G24 -> 0 | I24: =H24 -> 0 | J24: =I24 -> 0
B25: 持有至到期投资 | C25: 0 | D25: 0 | E25: 0 | F25: =E25 -> 0 | G25: =F25 -> 0 | H25: =G25 -> 0 | I25: =H25 -> 0 | J25: =I25 -> 0
B26: 债权投资 | C26: 851.93 | D26: 693.29 | E26: 975.27 | F26: =E26 -> 975.27 | G26: =F26 -> 975.27 | H26: =G26 -> 975.27 | I26: =H26 -> 975.27 | J26: =I26 -> 975.27
B27: 其他债权投资 | C27: 7893.94 | D27: 11094.26 | E27: 6319.05 | F27: =E27 -> 6319.05 | G27: =F27 -> 6319.05 | H27: =G27 -> 6319.05 | I27: =H27 -> 6319.05 | J27: =I27 -> 6319.05
B28: 长期应收款 | C28: 871.36 | D28: 614.6 | E28: 250.52 | F28: =E28 -> 250.52 | G28: =F28 -> 250.52 | H28: =G28 -> 250.52 | I28: =H28 -> 250.52 | J28: =I28 -> 250.52
B29: 长期股权投资 | C29: 3796.71 | D29: 5188.82 | E29: 4976.11 | F29: =E29 -> 4976.11 | G29: =F29 -> 4976.11 | H29: =G29 -> 4976.11 | I29: =H29 -> 4976.11 | J29: =I29 -> 4976.11
B30: 其他权益工具投资 | C30: 45.75 | D30: 41.36 | E30: 37.87 | F30: =E30 -> 37.87 | G30: =F30 -> 37.87 | H30: =G30 -> 37.87 | I30: =H30 -> 37.87 | J30: =I30 -> 37.87
B31: 其他非流动金融资产 | C31: 5912.87 | D31: 10625.24 | E31: 7769.94 | F31: =E31 -> 7769.94 | G31: =F31 -> 7769.94 | H31: =G31 -> 7769.94 | I31: =H31 -> 7769.94 | J31: =I31 -> 7769.94
B32: 投资性房地产 | C32: 859.2 | D32: 809.94 | E32: 1293.63 | F32: =E32 -> 1293.63 | G32: =F32 -> 1293.63 | H32: =G32 -> 1293.63 | I32: =H32 -> 1293.63 | J32: =I32 -> 1293.63
B33: 固定资产 | C33: 22852.85 | D33: 26082.99 | E33: 30937.96 | F33: =DA!F4 -> 35850.181 | G33: =DA!G4 -> 41039.114 | H33: =DA!H4 -> 46228.048 | I33: =DA!I4 -> 56876.201 | J33: =DA!J4 -> 62075.135
B34: 在建工程 | C34: 2690.93 | D34: 3843.78 | E34: 4681.22 | F34: =DA!F5 -> 4981.22 | G34: =DA!G5 -> 5281.22 | H34: =DA!H5 -> 5449.22 | I34: =DA!I5 -> 0 | J34: =DA!J5 -> 0
B35: 生产性生物资产 | C35: 0 | D35: 0 | E35: 0 | F35: =E35 -> 0 | G35: =F35 -> 0 | H35: =G35 -> 0 | I35: =H35 -> 0 | J35: =I35 -> 0
B36: 油气资产 | C36: 0 | D36: 0 | E36: 0 | F36: =E36 -> 0 | G36: =F36 -> 0 | H36: =G36 -> 0 | I36: =H36 -> 0 | J36: =I36 -> 0
B37: 使用权资产 | C37: 2297.35 | D37: 2339.88 | E37: 3048.79 | F37: =DA!F6 -> 5327.3465 | G37: =DA!G6 -> 7734.2574 | H37: =DA!H6 -> 10296.968 | I37: =DA!I6 -> 13049.353 | J37: =DA!J6 -> 16033.376
B38: 无形资产 | C38: 17173.07 | D38: 16908.92 | E38: 18457.74 | F38: =DA!F7 -> 18787.242 | G38: =DA!G7 -> 19135.306 | H38: =DA!H7 -> 19505.9 | I38: =DA!I7 -> 19903.922 | J38: =DA!J7 -> 20301.945
B39: 开发支出 | C39: 0 | D39: 0 | E39: 0 | F39: =DA!F8 -> 0 | G39: =DA!G8 -> 0 | H39: =DA!H8 -> 0 | I39: =DA!I8 -> 0 | J39: =DA!J8 -> 0
B40: 商誉 | C40: 27874.75 | D40: 28548.65 | E40: 30858.24 | F40: =E40 -> 30858.24 | G40: =F40 -> 30858.24 | H40: =G40 -> 30858.24 | I40: =H40 -> 30858.24 | J40: =I40 -> 30858.24
B41: 长期待摊费用 | C41: 1394.24 | D41: 1579.9 | E41: 1736.2 | F41: =DA!F9 -> 1690.8245 | G41: =DA!G9 -> 1637.367 | H41: =DA!H9 -> 1576.6813 | I41: =DA!I9 -> 1509.8397 | J41: =DA!J9 -> 1438.1948
B42: 递延所得税资产 | C42: 8192.31 | D42: 10244.3 | E42: 12771.15 | F42: =AVERAGE(C42:E42) -> 10402.587 | G42: =F42 -> 10402.587 | H42: =G42 -> 10402.587 | I42: =H42 -> 10402.587 | J42: =I42 -> 10402.587 | L42: 按前三年均值
...

Sheet CF
B2: 单位：百万元 | C2: =Assumptions!C2 -> 2021 | D2: =Assumptions!D2 -> 2022 | E2: =Assumptions!E2 -> 2023 | F2: =Assumptions!F2 -> 2024 | G2: =Assumptions!G2 -> 2025 | H2: =Assumptions!H2 -> 2026 | I2: =Assumptions!I2 -> 2027 | J2: =Assumptions!J2 -> 2028
B4: 经营性现金流
B5: 净利润 | F5: =IS!F24 -> 35048.704 | G5: =IS!G24 -> 36525.791 | H5: =IS!H24 -> 38388.3 | I5: =IS!I24 -> 40778.112 | J5: =IS!J24 -> 43840.166
B6: 加：折旧摊销 | F6: =IS!F30 -> 209.30383 | G6: =IS!G30 -> 226.6201 | H6: =IS!H30 -> 245.05725 | I6: =IS!I30 -> 264.85898 | J6: =IS!J30 -> 286.32722
B7: 减：非经常性/非经营性现金流 | F7: =-IS!F12 -> -1884.4133 | G7: =-IS!G12 -> -1884.4133 | H7: =-IS!H12 -> -1884.4133 | I7: =-IS!I12 -> -1884.4133 | J7: =-IS!J12 -> -1884.4133
B8: 减：财务费用 | F8: =-IS!F11 -> 918.15247 | G8: =-IS!G11 -> 678.80716 | H8: =-IS!H11 -> 455.38935 | I8: =-IS!I11 -> 208.4273 | J8: =-IS!J11 -> -67.247942
B9: 净营运资金的变化 | F9: =-(OWC!F26-OWC!E26) -> 4300.6199 | G9: =-(OWC!G26-OWC!F26) -> 2308.192 | H9: =-(OWC!H26-OWC!G26) -> 2783.3763 | I9: =-(OWC!I26-OWC!H26) -> 3366.1591 | J9: =-(OWC!J26-OWC!I26) -> 4083.4818
B10: 递延所得税资产的变化 | F10: =-(BS!F42-BS!E42) -> 2368.5633 | G10: =-(BS!G42-BS!F42) -> 0 | H10: =-(BS!H42-BS!G42) -> 0 | I10: =-(BS!I42-BS!H42) -> 0 | J10: =-(BS!J42-BS!I42) -> 0
B11: 其他非流动资产的变化 | F11: =-(BS!F43-BS!E43) -> 0 | G11: =-(BS!G43-BS!F43) -> 0 | H11: =-(BS!H43-BS!G43) -> 0 | I11: =-(BS!I43-BS!H43) -> 0 | J11: =-(BS!J43-BS!I43) -> 0
B12: 长期应付款的变化 | F12: =BS!F69-BS!E69 -> 0 | G12: =BS!G69-BS!F69 -> 0 | H12: =BS!H69-BS!G69 -> 0 | I12: =BS!I69-BS!H69 -> 0 | J12: =BS!J69-BS!I69 -> 0
B13: 预计负债的变化 | F13: =BS!F70-BS!E70 -> 0 | G13: =BS!G70-BS!F70 -> 0 | H13: =BS!H70-BS!G70 -> 0 | I13: =BS!I70-BS!H70 -> 0 | J13: =BS!J70-BS!I70 -> 0
B14: 递延收益-非流动负债的变化 | F14: =BS!F71-BS!E71 -> 0 | G14: =BS!G71-BS!F71 -> 0 | H14: =BS!H71-BS!G71 -> 0 | I14: =BS!I71-BS!H71 -> 0 | J14: =BS!J71-BS!I71 -> 0
B15: 递延所得税负债的变化 | F15: =BS!F72-BS!E72 -> 0 | G15: =BS!G72-BS!F72 -> 0 | H15: =BS!H72-BS!G72 -> 0 | I15: =BS!I72-BS!H72 -> 0 | J15: =BS!J72-BS!I72 -> 0
B16: 其他非流动负债的变化 | F16: =BS!F73-BS!E73 -> 0 | G16: =BS!G73-BS!F73 -> 0 | H16: =BS!H73-BS!G73 -> 0 | I16: =BS!I73-BS!H73 -> 0 | J16: =BS!J73-BS!I73 -> 0
B17: 经营性现金流 | F17: =SUM(F5:F16) -> 40960.93 | G17: =SUM(G5:G16) -> 37854.997 | H17: =SUM(H5:H16) -> 39987.71 | I17: =SUM(I5:I16) -> 42733.144 | J17: =SUM(J5:J16) -> 46258.314
B19: 投资活动现金流
B20: 交易性金融资产的变化 | F20: =-(BS!F6-BS!E6) -> 0 | G20: =-(BS!G6-BS!F6) -> 0 | H20: =-(BS!H6-BS!G6) -> 0 | I20: =-(BS!I6-BS!H6) -> 0 | J20: =-(BS!J6-BS!I6) -> 0
B21: 衍生金融资产的变化 | F21: =-(BS!F7-BS!E7) -> 0 | G21: =-(BS!G7-BS!F7) -> 0 | H21: =-(BS!H7-BS!G7) -> 0 | I21: =-(BS!I7-BS!H7) -> 0 | J21: =-(BS!J7-BS!I7) -> 0
B22: 以公允价值计量且其变动计入其他综合收益的金融资产的变化 | F22: =-(BS!F22-BS!E22) -> 0 | G22: =-(BS!G22-BS!F22) -> 0 | H22: =-(BS!H22-BS!G22) -> 0 | I22: =-(BS!I22-BS!H22) -> 0 | J22: =-(BS!J22-BS!I22) -> 0
B23: 以摊余成本计量的金融资产的变化 | F23: =-(BS!F23-BS!E23) -> 0 | G23: =-(BS!G23-BS!F23) -> 0 | H23: =-(BS!H23-BS!G23) -> 0 | I23: =-(BS!I23-BS!H23) -> 0 | J23: =-(BS!J23-BS!I23) -> 0
B24: 可供出售金融资产的变化 | F24: =-(BS!F24-BS!E24) -> 0 | G24: =-(BS!G24-BS!F24) -> 0 | H24: =-(BS!H24-BS!G24) -> 0 | I24: =-(BS!I24-BS!H24) -> 0 | J24: =-(BS!J24-BS!I24) -> 0
B25: 持有至到期投资的变化 | F25: =-(BS!F25-BS!E25) -> 0 | G25: =-(BS!G25-BS!F25) -> 0 | H25: =-(BS!H25-BS!G25) -> 0 | I25: =-(BS!I25-BS!H25) -> 0 | J25: =-(BS!J25-BS!I25) -> 0
B26: 债权投资的变化 | F26: =-(BS!F26-BS!E26) -> 0 | G26: =-(BS!G26-BS!F26) -> 0 | H26: =-(BS!H26-BS!G26) -> 0 | I26: =-(BS!I26-BS!H26) -> 0 | J26: =-(BS!J26-BS!I26) -> 0
B27: 其他债权投资的变化 | F27: =-(BS!F27-BS!E27) -> 0 | G27: =-(BS!G27-BS!F27) -> 0 | H27: =-(BS!H27-BS!G27) -> 0 | I27: =-(BS!I27-BS!H27) -> 0 | J27: =-(BS!J27-BS!I27) -> 0
B28: 长期应收款的变化 | F28: =-(BS!F28-BS!E28) -> 0 | G28: =-(BS!G28-BS!F28) -> 0 | H28: =-(BS!H28-BS!G28) -> 0 | I28: =-(BS!I28-BS!H28) -> 0 | J28: =-(BS!J28-BS!I28) -> 0
B29: 长期股权投资的变化 | F29: =-(BS!F29-BS!E29) -> 0 | G29: =-(BS!G29-BS!F29) -> 0 | H29: =-(BS!H29-BS!G29) -> 0 | I29: =-(BS!I29-BS!H29) -> 0 | J29: =-(BS!J29-BS!I29) -> 0
B30: 其他权益工具投资的变化 | F30: =-(BS!F30-BS!E30) -> 0 | G30: =-(BS!G30-BS!F30) -> 0 | H30: =-(BS!H30-BS!G30) -> 0 | I30: =-(BS!I30-BS!H30) -> 0 | J30: =-(BS!J30-BS!I30) -> 0
B31: 其他非流动金融资产的变化 | F31: =-(BS!F31-BS!E31) -> 0 | G31: =-(BS!G31-BS!F31) -> 0 | H31: =-(BS!H31-BS!G31) -> 0 | I31: =-(BS!I31-BS!H31) -> 0 | J31: =-(BS!J31-BS!I31) -> 0
B32: 投资性房地产的变化 | F32: =-(BS!F32-BS!E32) -> 0 | G32: =-(BS!G32-BS!F32) -> 0 | H32: =-(BS!H32-BS!G32) -> 0 | I32: =-(BS!I32-BS!H32) -> 0 | J32: =-(BS!J32-BS!I32) -> 0
B33: 固定资产的购置 | F33: =-DA!F41 -> -4912.2207 | G33: =-DA!G41 -> -5188.9335 | H33: =-DA!H41 -> -5188.9335 | I33: =-DA!I41 -> -5188.9335 | J33: =-DA!J41 -> -5188.9335
B34: 固定资产-非同一控制下企业合并付出的对价 | F34: =-DA!F43 -> 0 | G34: =-DA!G43 -> 0 | H34: =-DA!H43 -> 0 | I34: =-DA!I43 -> 0 | J34: =-DA!J43 -> 0
B35: 在建工程的购置 | F35: =-DA!F68 -> -300 | G35: =-DA!G68 -> -300 | H35: =-DA!H68 -> -168 | I35: =-DA!I68 -> -10 | J35: =-DA!J68 -> -10
B36: 生产性生物资产的变化 | F36: =-(BS!F35-BS!E35) -> 0 | G36: =-(BS!G35-BS!F35) -> 0 | H36: =-(BS!H35-BS!G35) -> 0 | I36: =-(BS!I35-BS!H35) -> 0 | J36: =-(BS!J35-BS!I35) -> 0
B37: 油气资产的变化 | F37: =-(BS!F36-BS!E36) -> 0 | G37: =-(BS!G36-BS!F36) -> 0 | H37: =-(BS!H36-BS!G36) -> 0 | I37: =-(BS!I36-BS!H36) -> 0 | J37: =-(BS!J36-BS!I36) -> 0
B38: 使用权资产的购置 | F38: =-DA!F95 -> -2278.5565 | G38: =-DA!G95 -> -2406.911 | H38: =-DA!H95 -> -2562.7107 | I38: =-DA!I95 -> -2752.3846 | J38: =-DA!J95 -> -2984.0232
B39: 使用权资产-非同一控制下企业合并付出的对价 | F39: =-DA!F96 -> 0 | G39: =-DA!G96 -> 0 | H39: =-DA!H96 -> 0 | I39: =-DA!I96 -> 0 | J39: =-DA!J96 -> 0
B40: 无形资产的购置 | F40: =-DA!F132 -> -329.50222 | G40: =-DA!G132 -> -348.06357 | H40: =-DA!H132 -> -370.59378 | I40: =-DA!I132 -> -398.02253 | J40: =-DA!J132 -> -398.02253
B41: 无形资产-非同一控制下企业合并付出的对价 | F41: =-DA!F133 -> 0 | G41: =-DA!G133 -> 0 | H41: =-DA!H133 -> 0 | I41: =-DA!I133 -> 0 | J41: =-DA!J133 -> 0
B42: 开发支出的购置 | F42: =-DA!F158 -> 0 | G42: =-DA!G158 -> 0 | H42: =-DA!H158 -> 0 | I42: =-DA!I158 -> 0 | J42: =-DA!J158 -> 0
B43: 商誉的变化 | F43: =-(BS!F40-BS!E40) -> 0 | G43: =-(BS!G40-BS!F40) -> 0 | H43: =-(BS!H40-BS!G40) -> 0 | I43: =-(BS!I40-BS!H40) -> 0 | J43: =-(BS!J40-BS!I40) -> 0
...

Sheet OWC
B2: 单位：百万元 | C2: =Assumptions!C2 -> 2021 | D2: =Assumptions!D2 -> 2022 | E2: =Assumptions!E2 -> 2023 | F2: =Assumptions!F2 -> 2024 | G2: =Assumptions!G2 -> 2025 | H2: =Assumptions!H2 -> 2026 | I2: =Assumptions!I2 -> 2027 | J2: =Assumptions!J2 -> 2028
B4: 应收票据 | D4: =BS!D8 -> 4758.13 | E4: =BS!E8 -> 5521.96 | F4: =BS!F8 -> 5791.4628 | G4: =BS!G8 -> 6117.7046 | H4: =BS!H8 -> 6513.7045 | I4: =BS!I8 -> 6995.8033 | J4: =BS!J8 -> 7584.5649
B5: 应收账款 | D5: =BS!D9 -> 28237.97 | E5: =BS!E9 -> 32884.74 | F5: =BS!F9 -> 34489.701 | G5: =BS!G9 -> 36432.557 | H5: =BS!H9 -> 38790.842 | I5: =BS!I9 -> 41661.868 | J5: =BS!J9 -> 45168.1
B6: 应收款项融资 | D6: =BS!D10 -> 13526.54 | E6: =BS!E10 -> 13330.01 | F6: =BS!F10 -> 13980.59 | G6: =BS!G10 -> 14768.137 | H6: =BS!H10 -> 15724.081 | I6: =BS!I10 -> 16887.867 | J6: =BS!J10 -> 18309.138
B7: 预付款项 | D7: =BS!D11 -> 4367.21 | E7: =BS!E11 -> 3316.19 | F7: =BS!F11 -> 3433.6891 | G7: =BS!G11 -> 3631.5314 | H7: =BS!H11 -> 3870.2798 | I7: =BS!I11 -> 4159.2342 | J7: =BS!J11 -> 4510.0317
B8: 其他应收款 | D8: =BS!D12 -> 2211.18 | E8: =BS!E12 -> 2181.88 | F8: =BS!F12 -> 2499.0433 | G8: =BS!G12 -> 2499.0433 | H8: =BS!H12 -> 2499.0433 | I8: =BS!I12 -> 2499.0433 | J8: =BS!J12 -> 2499.0433
B9: 存货 | D9: =BS!D13 -> 46044.9 | E9: =BS!E13 -> 47339.26 | F9: =BS!F13 -> 49016.583 | G9: =BS!G13 -> 51840.82 | H9: =BS!H13 -> 55249 | I9: =BS!I13 -> 59373.88 | J9: =BS!J13 -> 64381.583
B10: 合同资产 | D10: =BS!D14 -> 4498.96 | E10: =BS!E14 -> 4045.93 | F10: =BS!F14 -> 4243.3942 | G10: =BS!G14 -> 4482.431 | H10: =BS!H14 -> 4772.5794 | I10: =BS!I14 -> 5125.8123 | J10: =BS!J14 -> 5557.1968
B11: 持有待售资产 | D11: =BS!D15 -> 0 | E11: =BS!E15 -> 0 | F11: =BS!F15 -> 0 | G11: =BS!G15 -> 0 | H11: =BS!H15 -> 0 | I11: =BS!I15 -> 0 | J11: =BS!J15 -> 0
B12: 一年内到期的非流动资产 | D12: =BS!D16 -> 37553.08 | E12: =BS!E16 -> 10760.58 | F12: =BS!F16 -> 22721.747 | G12: =BS!G16 -> 22721.747 | H12: =BS!H16 -> 22721.747 | I12: =BS!I16 -> 22721.747 | J12: =BS!J16 -> 22721.747
B13: 其他流动资产 | D13: =BS!D17 -> 46542.38 | E13: =BS!E17 -> 62900.89 | F13: =BS!F17 -> 47533.093 | G13: =BS!G17 -> 47533.093 | H13: =BS!H17 -> 47533.093 | I13: =BS!I17 -> 47533.093 | J13: =BS!J17 -> 47533.093
B14: 非现金流动资产 | D14: =SUM(D4:D13) -> 187740.35 | E14: =SUM(E4:E13) -> 182281.44 | F14: =SUM(F4:F13) -> 183709.3 | G14: =SUM(G4:G13) -> 190027.06 | H14: =SUM(H4:H13) -> 197674.37 | I14: =SUM(I4:I13) -> 206958.35 | J14: =SUM(J4:J13) -> 218264.5
B16: 应付票据 | D16: =BS!D53 -> 25572.42 | E16: =BS!E53 -> 21707.61 | F16: =BS!F53 -> 22476.753 | G16: =BS!G53 -> 23771.818 | H16: =BS!H53 -> 25334.653 | I16: =BS!I53 -> 27226.134 | J16: =BS!J53 -> 29522.436
B17: 应付账款 | D17: =BS!D54 -> 64233.23 | E17: =BS!E54 -> 72530.47 | F17: =BS!F54 -> 75100.367 | G17: =BS!G54 -> 79427.499 | H17: =BS!H54 -> 84649.315 | I17: =BS!I54 -> 90969.217 | J17: =BS!J54 -> 98641.729
B18: 预收款项 | D18: =BS!D55 -> 0 | E18: =BS!E55 -> 0 | F18: =BS!F55 -> 0 | G18: =BS!G55 -> 0 | H18: =BS!H55 -> 0 | I18: =BS!I55 -> 0 | J18: =BS!J55 -> 0
B19: 合同负债 | D19: =BS!D56 -> 27960.04 | E19: =BS!E56 -> 41765.48 | F19: =BS!F56 -> 43803.871 | G19: =BS!G56 -> 46271.409 | H19: =BS!H56 -> 49266.564 | I19: =BS!I56 -> 52912.93 | J19: =BS!J56 -> 57366.043
B20: 应付职工薪酬 | D20: =BS!D57 -> 7152.22 | E20: =BS!E57 -> 9076.03 | F20: =BS!F57 -> 9518.9915 | G20: =BS!G57 -> 10055.21 | H20: =BS!H57 -> 10706.086 | I20: =BS!I57 -> 11498.475 | J20: =BS!J57 -> 12466.178
B21: 应交税费 | D21: =BS!D58 -> 4955.34 | E21: =BS!E58 -> 5455.1 | F21: =BS!F58 -> 5455.1 | G21: =BS!G58 -> 5455.1 | H21: =BS!H58 -> 5455.1 | I21: =BS!I58 -> 5455.1 | J21: =BS!J58 -> 5455.1
B22: 其他应付款 | D22: =BS!D59 -> 4322.03 | E22: =BS!E59 -> 4442.93 | F22: =BS!F59 -> 4351.02 | G22: =BS!G59 -> 4351.02 | H22: =BS!H59 -> 4351.02 | I22: =BS!I59 -> 4351.02 | J22: =BS!J59 -> 4351.02
B23: 其他流动负债 | D23: =BS!D62 -> 57843.53 | E23: =BS!E62 -> 71297.93 | F23: =BS!F62 -> 71297.93 | G23: =BS!G62 -> 71297.93 | H23: =BS!H62 -> 71297.93 | I23: =BS!I62 -> 71297.93 | J23: =BS!J62 -> 71297.93
B24: 非借款的流动负债 | D24: =SUM(D16:D23) -> 192038.81 | E24: =SUM(E16:E23) -> 226275.55 | F24: =SUM(F16:F23) -> 232004.03 | G24: =SUM(G16:G23) -> 240629.99 | H24: =SUM(H16:H23) -> 251060.67 | I24: =SUM(I16:I23) -> 263710.81 | J24: =SUM(J16:J23) -> 279100.44
B26: 净营运资金 | D26: =D14-D24 -> -4298.46 | E26: =E14-E24 -> -43994.11 | F26: =F14-F24 -> -48294.73 | G26: =G14-G24 -> -50602.922 | H26: =H14-H24 -> -53386.298 | I26: =I14-I24 -> -56752.457 | J26: =J14-J24 -> -60835.939

Sheet DA
B2: 单位：百万元 | C2: =Assumptions!C2 -> 2021 | D2: =Assumptions!D2 -> 2022 | E2: =Assumptions!E2 -> 2023 | F2: =Assumptions!F2 -> 2024 | G2: =Assumptions!G2 -> 2025 | H2: =Assumptions!H2 -> 2026 | I2: =Assumptions!I2 -> 2027 | J2: =Assumptions!J2 -> 2028 | L2: 备注
B4: 固定资产账面价值 | E4: =BS!E33 -> 30937.96 | F4: =E4+F44+F56 -> 35850.181 | G4: =F4+G44+G56 -> 41039.114 | H4: =G4+H44+H56 -> 46228.048 | I4: =H4+I44+I56 -> 56876.201 | J4: =I4+J44+J56 -> 62075.135
B5: 在建工程账面价值 | F5: =F71 -> 4981.22 | G5: =G71 -> 5281.22 | H5: =H71 -> 5449.22 | I5: =I71 -> 0 | J5: =J71 -> 0
B6: 使用权资产账面价值 | E6: =BS!E37 -> 3048.79 | F6: =E6+F97+F108 -> 5327.3465 | G6: =F6+G97+G108 -> 7734.2574 | H6: =G6+H97+H108 -> 10296.968 | I6: =H6+I97+I108 -> 13049.353 | J6: =I6+J97+J108 -> 16033.376
B7: 无形资产账面价值 | D7: =BS!D38 -> 16908.92 | E7: =BS!E38 -> 18457.74 | F7: =E7+F135+F146 -> 18787.242 | G7: =F7+G135+G146 -> 19135.306 | H7: =G7+H135+H146 -> 19505.9 | I7: =H7+I135+I146 -> 19903.922 | J7: =I7+J135+J146 -> 20301.945
B8: 开发支出账面价值 | F8: =F161 -> 0 | G8: =G161 -> 0 | H8: =H161 -> 0 | I8: =I161 -> 0 | J8: =J161 -> 0
B9: 长期待摊费用账面价值 | E9: =BS!E41 -> 1736.2 | F9: =E9+F174+F185 -> 1690.8245 | G9: =F9+G174+G185 -> 1637.367 | H9: =G9+H174+H185 -> 1576.6813 | I9: =H9+I174+I185 -> 1509.8397 | J9: =I9+J174+J185 -> 1438.1948
B10: 折旧、摊销合计 | E10: =E56+E108+E146+E185 -> 0 | F10: =F56+F108+F146+F185 -> -209.30383 | G10: =G56+G108+G146+G185 -> -226.6201 | H10: =H56+H108+H146+H185 -> -245.05725 | I10: =I56+I108+I146+I185 -> -264.85898 | J10: =J56+J108+J146+J185 -> -286.32722
B12: 固定资产
B13: 固定资产原值期初额 | D13: 49877.675 | E13: 54866.862
B14: 本期增加-购置 | D14: 4801.944 | E14: 4683.633
B15: 本期增加-在建工程转入 | D15: 2110.91 | E15: 3466.612
B16: 本期增加-非同一控制下企业合并 | D16: 0 | E16: 0
B17: 本期减少-处置或报废 | D17: -1912.861 | E17: -2827.74
B18: 本期增加-外币折算 | D18: -30.252 | E18: 5.8
B19: 固定资产原值期末余额 | D19: =SUM(D13:D18) -> 54847.416 | E19: =SUM(E13:E18) -> 60195.167
B21: 累计折旧期初额 | D21: 26974.507 | E21: 28728.348
B22: 本期新增计提 | D22: 3365.445 | E22: 3703.285
B23: 本期增加-非同一控制下企业合并 | D23: 0 | E23: 0
B24: 本期减少-处置或报废 | D24: -1632.63 | E24: -1464.735
B25: 本期增加-外币折算 | D25: 13.078 | E25: -24.282
B26: 期末余额 | D26: =SUM(D21:D25) -> 28720.4 | E26: =SUM(E21:E25) -> 30942.616
B28: 固定资产账面价值期初额 | D28: =D13+D21 -> 76852.182 | E28: =E13+E21 -> 83595.21
B29: 固定资产账面价值期末额 | D29: =D19+D26 -> 83567.816 | E29: =E19+E26 -> 91137.783
B31: 固定资产原值 | D31: =D19 -> 54847.416 | E31: =E19 -> 60195.167
B32: 累计折旧 | D32: =D26 -> 28720.4 | E32: =E26 -> 30942.616
B33: 固定资产净值 | D33: =D31+D32 -> 83567.816 | E33: =E31+E32 -> 91137.783
B35: 现有固定资产净值 | D35: =D33 -> 83567.816 | E35: =E33 -> 91137.783
B36: 折旧年限 | C36: =IFERROR(ROUNDDOWN(AVERAGE(-D35/D22,-E35/E22),0),ROUNDDOWN(-E35/E22,0)) -> -24
B37: 残值率 | C37: 0.03
B38: 现有固定资产折旧 | F38: =-IF(F$2>$E$2+$C$36,0,SLN($E$35,$C$37,$C$36)) -> 0 | G38: =-IF(G$2>$E$2+$C$36,0,SLN($E$35,$C$37,$C$36)) -> 0 | H38: =-IF(H$2>$E$2+$C$36,0,SLN($E$35,$C$37,$C$36)) -> 0 | I38: =-IF(I$2>$E$2+$C$36,0,SLN($E$35,$C$37,$C$36)) -> 0 | J38: =-IF(J$2>$E$2+$C$36,0,SLN($E$35,$C$37,$C$36)) -> 0 | L38: 为粗略估算数
B40: 新增固定资产
B41: 购置 | D41: =D14 -> 4801.944 | E41: =E14 -> 4683.633 | F41: =E41*(1+Assumptions!F10) -> 4912.2207 | G41: =F41*(1+Assumptions!G10) -> 5188.9335 | H41: =G41 -> 5188.9335 | I41: =H41 -> 5188.9335 | J41: =I41 -> 5188.9335
B42: 在建工程转入 | D42: =D15 -> 2110.91 | E42: =E15 -> 3466.612 | F42: =-F69 -> 0 | G42: =-G69 -> 0 | H42: =-H69 -> 0 | I42: =-I69 -> 5459.22 | J42: =-J69 -> 10
B43: 非同一控制下企业合并 | E43: =E16 -> 0 | F43: =E43*(1+Assumptions!F10) -> 0 | G43: =F43*(1+Assumptions!G10) -> 0 | H43: =G43*(1+Assumptions!H10) -> 0 | I43: =H43*(1+Assumptions!I10) -> 0 | J43: =I43*(1+Assumptions!J10) -> 0
B44: 新增 | F44: =SUM(F41:F43) -> 4912.2207 | G44: =SUM(G41:G43) -> 5188.9335 | H44: =SUM(H41:H43) -> 5188.9335 | I44: =SUM(I41:I43) -> 10648.153 | J44: =SUM(J41:J43) -> 5198.9335
B45: 折旧年限 | C45: =C36+1 -> -23
B46: 残值率 | C46: 0.03
B47: 折旧
C48: {=TRANSPOSE(F2:J2)} -> 2024 | D48: {=TRANSPOSE(F44:J44)} -> 4912.2207 | F48: =-IF(AND(F$2>=$C48,F$2<$C48+$C$45),SLN($D48,$C$46,$C$45),0) -> 0 | G48: =-IF(AND(G$2>=$C48,G$2<$C48+$C$45),SLN($D48,$C$46,$C$45),0) -> 0 | H48: =-IF(AND(H$2>=$C48,H$2<$C48+$C$45),SLN($D48,$C$46,$C$45),0) -> 0 | I48: =-IF(AND(I$2>=$C48,I$2<$C48+$C$45),SLN($D48,$C$46,$C$45),0) -> 0 | J48: =-IF(AND(J$2>=$C48,J$2<$C48+$C$45),SLN($D48,$C$46,$C$45),0) -> 0
...

Sheet 收入拆分
B2: 单位：百万元 | C2: =Assumptions!C2 -> 2021 | D2: =Assumptions!D2 -> 2022 | E2: =Assumptions!E2 -> 2023 | F2: =Assumptions!F2 -> 2024 | G2: =Assumptions!G2 -> 2025 | H2: =Assumptions!H2 -> 2026 | I2: =Assumptions!I2 -> 2027 | J2: =Assumptions!J2 -> 2028 | L2: 说明
B4: 总收入 | C4: =C10+C16+C22+C28+C34+C40+C46+C52+C58 -> 312259.83 | D4: =D10+D16+D22+D28+D34+D40+D46+D52+D58 -> 320233.61 | E4: =E10+E16+E22+E28+E34+E40+E46+E52+E58 -> 348772.97 | F4: =F10+F16+F22+F28+F34+F40+F46+F52+F58 -> 365795.06 | G4: =G10+G16+G22+G28+G34+G40+G46+G52+G58 -> 386400.84 | H4: =H10+H16+H22+H28+H34+H40+H46+H52+H58 -> 411412.62 | I4: =I10+I16+I22+I28+I34+I40+I46+I52+I58 -> 441862.5 | J4: =J10+J16+J22+J28+J34+J40+J46+J52+J58 -> 479049.32 | L4: 因此预测收入增长按照公司均能达成预测值
B5: 增长率（%） | C5: =C4/#REF!-1 -> #REF! | D5: =D4/C4-1 -> 0.025535702 | E5: =E4/D4-1 -> 0.089120441 | F5: =F4/E4-1 -> 0.04880564 | G5: =G4/F4-1 -> 0.056331497 | H5: =H4/G4-1 -> 0.064730149 | I5: =I4/H4-1 -> 0.074012993 | J5: =J4/I4-1 -> 0.084159259
B6: 总成本 | C6: =C12+C18+C24+C30+C36+C42+C48+C54+C60 -> -237288.37 | D6: =D12+D18+D24+D30+D36+D42+D48+D54+D60 -> -239558.12 | E6: =E12+E18+E24+E30+E36+E42+E48+E54+E60 -> -252116.51 | F6: =(F12+F18+F24+F30+F36+F42+F48+F54+F60) -> -264275.95 | G6: =(G12+G18+G24+G30+G36+G42+G48+G54+G60) -> -279503 | H6: =(H12+H18+H24+H30+H36+H42+H48+H54+H60) -> -297878.42 | I6: =(I12+I18+I24+I30+I36+I42+I48+I54+I60) -> -320117.96 | J6: =(J12+J18+J24+J30+J36+J42+J48+J54+J60) -> -347117.3
B7: 毛利率（%） | C7: =1-(-C6/C4) -> 0.2400932 | D7: =1-(-D6/D4) -> 0.25192699 | E7: =1-(-E6/E4) -> 0.27713289 | F7: =1-(-F6/F4) -> 0.27753001 | G7: =1-(-G6/G4) -> 0.27665013 | H7: =1-(-H6/H4) -> 0.2759619 | I7: =1-(-I6/I4) -> 0.27552585 | J7: =1-(-J6/J4) -> 0.27540383
B9: Smart Home Solutions
B10: 收入 | C10: 234918 | D10: 232825 | E10: 246351 | F10: =E10*(1+F11) -> 246351 | G10: =F10*(1+G11) -> 246351 | H10: =G10*(1+H11) -> 246351 | I10: =H10*(1+I11) -> 246351 | J10: =I10*(1+J11) -> 246351
B11: 增长率（%） | C11: =C10/#REF!-1 -> #REF! | D11: =D10/C10-1 -> -0.0089094918 | E11: =(E10/C10)^0.5-1 -> 0.024044943 | F11: 0 | G11: =F11 -> 0 | H11: =G11 -> 0 | I11: =H11 -> 0 | J11: =I11 -> 0 | L11: 假设公司产品增速维持平均增长的基础上有所下降
B12: 成本 | C12: =IFERROR(-C10*(1-C13),0) -> -175953.58 | D12: =IFERROR(-D10*(1-D13),0) -> -169962.25 | E12: =IFERROR(-E10*(1-E13),0) -> -172938.4 | F12: =IFERROR(-F10*(1-F13),0) -> -172445.7 | G12: =IFERROR(-G10*(1-G13),0) -> -172445.7 | H12: =IFERROR(-H10*(1-H13),0) -> -172445.7 | I12: =IFERROR(-I10*(1-I13),0) -> -172445.7 | J12: =IFERROR(-J10*(1-J13),0) -> -172445.7
B13: 毛利率（%） | C13: 0.251 | D13: 0.27 | E13: 0.298 | F13: =E13+0.002 -> 0.3 | G13: =F13 -> 0.3 | H13: =G13 -> 0.3 | I13: =H13 -> 0.3 | J13: =I13 -> 0.3 | L13: 毛利率呈现小幅波动，保守按照2023年数预计
B15: Commercial & Industrial Solutions
B16: 收入 | C16: 73379 | D16: 83639 | E16: 97781 | F16: =E16*(1+F17) -> 114803.09 | G16: =F16*(1+G17) -> 135362.46 | H16: =G16*(1+H17) -> 160280.5 | I16: =H16*(1+I17) -> 190586.94 | J16: =I16*(1+J17) -> 227576.78
B17: 增长率（%） | C17: =C16/#REF!-1 -> #REF! | D17: =D16/C16-1 -> 0.13982202 | E17: =E16/D16-1 -> 0.1690838 | F17: =E17+0.5% -> 0.1740838 | G17: =F17+0.5% -> 0.1790838 | H17: =G17+0.5% -> 0.1840838 | I17: =H17+0.5% -> 0.1890838 | J17: =I17+0.5% -> 0.1940838 | L17: 假设公司产品略微增长
B18: 成本 | C18: =IFERROR(-C16*(1-C19),0) -> -58996.716 | D18: =IFERROR(-D16*(1-D19),0) -> -66994.839 | E18: =IFERROR(-E16*(1-E19),0) -> -75975.837 | F18: =IFERROR(-F16*(1-F19),0) -> -88627.984 | G18: =IFERROR(-G16*(1-G19),0) -> -103823.01 | H18: =IFERROR(-H16*(1-H19),0) -> -122133.74 | I18: =IFERROR(-I16*(1-I19),0) -> -144274.32 | J18: =IFERROR(-J16*(1-J19),0) -> -171137.74
B19: 毛利率（%） | C19: 0.196 | D19: 0.199 | E19: 0.223 | F19: =E19+0.5% -> 0.228 | G19: =F19+0.5% -> 0.233 | H19: =G19+0.5% -> 0.238 | I19: =H19+0.5% -> 0.243 | J19: =I19+0.5% -> 0.248 | L19: 毛利率呈现小幅波动，保守按照2022年数预计
B21: 其他
B22: 收入 | C22: 3962.8344 | D22: 3769.6083 | E22: 4640.9686 | F22: =E22*(1+F23) -> 4640.9686 | G22: =F22*(1+G23) -> 4687.3782 | H22: =G22*(1+H23) -> 4781.1258 | I22: =H22*(1+I23) -> 4924.5596 | J22: =I22*(1+J23) -> 5121.542
B23: 增长率（%） | C23: =C22/#REF!-1 -> #REF! | D23: =D22/C22-1 -> -0.048759562 | E23: =E22/D22-1 -> 0.23115406 | F23: 0 | G23: =F23+1% -> 0.01 | H23: =G23+1% -> 0.02 | I23: =H23+1% -> 0.03 | J23: =I23+1% -> 0.04 | L23: 维持一定增长
B24: 成本 | C24: -2338.0723 | D24: -2601.0297 | E24: -3202.2683 | F24: =IFERROR(-F22*(1-F25),0) -> -3202.2683 | G24: =IFERROR(-G22*(1-G25),0) -> -3234.291 | H24: =IFERROR(-H22*(1-H25),0) -> -3298.9768 | I24: =IFERROR(-I22*(1-I25),0) -> -3397.9461 | J24: =IFERROR(-J22*(1-J25),0) -> -3533.864
B25: 毛利率（%） | C25: =1-(-C24/C22) -> 0.41 | D25: =1-(-D24/D22) -> 0.31 | E25: =1-(-E24/E22) -> 0.31 | F25: 0.31 | G25: =F25 -> 0.31 | H25: =G25 -> 0.31 | I25: =H25 -> 0.31 | J25: =I25 -> 0.31 | L25: 毛利率呈现小幅波动，假设按照前几年平均数
B33: **业务
B34: 收入 | C34: 0 | D34: 0 | E34: 0 | F34: =E34*(1+F35) -> 0 | G34: =F34*(1+G35) -> 0 | H34: =G34*(1+H35) -> 0 | I34: =H34*(1+I35) -> 0 | J34: =I34*(1+J35) -> 0
B35: 增长率（%） | C35: =C34/#REF!-1 -> #REF! | D35: =D34/C34-1 -> #DIV/0! | E35: =E34/D34-1 -> #DIV/0! | F35: 0.12 | G35: 0.1 | H35: 0.08 | I35: =H35 -> 0.08 | J35: =I35 -> 0.08
B36: 成本 | C36: 0 | D36: 0 | E36: 0 | F36: =IFERROR(-F34*(1-F37),0) -> 0 | G36: =IFERROR(-G34*(1-G37),0) -> 0 | H36: =IFERROR(-H34*(1-H37),0) -> 0 | I36: =IFERROR(-I34*(1-I37),0) -> 0 | J36: =IFERROR(-J34*(1-J37),0) -> 0
B37: 毛利率（%） | C37: =1-(-C36/C34) -> #DIV/0! | D37: =1-(-D36/D34) -> #DIV/0! | E37: =1-(-E36/E34) -> #DIV/0! | F37: =E37 -> #DIV/0! | G37: =F37 -> #DIV/0! | H37: =G37 -> #DIV/0! | I37: =H37 -> #DIV/0! | J37: =I37 -> #DIV/0!
B39: **业务
B40: 收入 | C40: 0 | D40: 0 | E40: 0 | F40: =E40*(1+F41) -> 0 | G40: =F40*(1+G41) -> 0 | H40: =G40*(1+H41) -> 0 | I40: =H40*(1+I41) -> 0 | J40: =I40*(1+J41) -> 0
B41: 增长率（%） | C41: =C40/#REF!-1 -> #REF! | D41: =D40/C40-1 -> #DIV/0! | E41: =E40/D40-1 -> #DIV/0! | F41: -0.2 | G41: -0.1 | H41: =G41+2% -> -0.08 | I41: =H41 -> -0.08 | J41: =I41 -> -0.08
B42: 成本 | C42: 0 | D42: 0 | E42: 0 | F42: =IFERROR(-F40*(1-F43),0) -> 0 | G42: =IFERROR(-G40*(1-G43),0) -> 0 | H42: =IFERROR(-H40*(1-H43),0) -> 0 | I42: =IFERROR(-I40*(1-I43),0) -> 0 | J42: =IFERROR(-J40*(1-J43),0) -> 0
B43: 毛利率（%） | C43: =1-(-C42/C40) -> #DIV/0! | D43: =1-(-D42/D40) -> #DIV/0! | E43: =1-(-E42/E40) -> #DIV/0! | F43: =E43 -> #DIV/0! | G43: =F43 -> #DIV/0! | H43: =G43 -> #DIV/0! | I43: =H43 -> #DIV/0! | J43: =I43 -> #DIV/0!
B45: **业务
B46: 收入 | C46: 0 | D46: 0 | E46: 0 | F46: =E46*(1+F47) -> 0 | G46: =F46*(1+G47) -> 0 | H46: =G46*(1+H47) -> 0 | I46: =H46*(1+I47) -> 0 | J46: =I46*(1+J47) -> 0
B47: 增长率（%） | C47: =C46/#REF!-1 -> #REF! | D47: =D46/C46-1 -> #DIV/0! | E47: =E46/D46-1 -> #DIV/0! | F47: 0 | G47: 0 | H47: 0 | I47: 0 | J47: 0
B48: 成本 | C48: 0 | D48: 0 | E48: 0 | F48: =IFERROR(-F46*(1-F49),0) -> 0 | G48: =IFERROR(-G46*(1-G49),0) -> 0 | H48: =IFERROR(-H46*(1-H49),0) -> 0 | I48: =IFERROR(-I46*(1-I49),0) -> 0 | J48: =IFERROR(-J46*(1-J49),0) -> 0
B49: 毛利率（%） | C49: =1-(-C48/C46) -> #DIV/0! | D49: =1-(-D48/D46) -> #DIV/0! | E49: =1-(-E48/E46) -> #DIV/0! | F49: 0 | G49: 0 | H49: 0 | I49: 0 | J49: 0
B51: **业务
B52: 收入 | C52: 0 | D52: 0 | E52: 0 | F52: =E52*(1+F53) -> 0 | G52: =F52*(1+G53) -> 0 | H52: =G52*(1+H53) -> 0 | I52: =H52*(1+I53) -> 0 | J52: =I52*(1+J53) -> 0
B53: 增长率（%） | C53: =C52/#REF!-1 -> #REF! | D53: =D52/C52-1 -> #DIV/0! | E53: =E52/D52-1 -> #DIV/0! | F53: 0 | G53: 0 | H53: 0 | I53: 0 | J53: 0
B54: 成本 | C54: 0 | D54: 0 | E54: 0 | F54: =IFERROR(-F52*(1-F55),0) -> 0 | G54: =IFERROR(-G52*(1-G55),0) -> 0 | H54: =IFERROR(-H52*(1-H55),0) -> 0 | I54: =IFERROR(-I52*(1-I55),0) -> 0 | J54: =IFERROR(-J52*(1-J55),0) -> 0
B55: 毛利率（%） | C55: =1-(-C54/C52) -> #DIV/0! | D55: =1-(-D54/D52) -> #DIV/0! | E55: =1-(-E54/E52) -> #DIV/0! | F55: =D55 -> #DIV/0! | G55: =F55 -> #DIV/0! | H55: =G55 -> #DIV/0! | I55: =H55 -> #DIV/0! | J55: =I55 -> #DIV/0!
...

Sheet Assumptions
B2: 单位：百万元 | C2: =D2-1 -> 2021 | D2: =E2-1 -> 2022 | E2: =F2-1 -> 2023 | F2: =F4 -> 2024 | G2: =F2+1 -> 2025 | H2: =G2+1 -> 2026 | I2: =H2+1 -> 2027 | J2: =I2+1 -> 2028 | L2: 备注
B4: 估值预测第一年 | F4: 2024
B6: PL
B8: 情形选择 | C8: 2 | D8: =CHOOSE(C8,"保守情形","基本情形","乐观情形") -> 基本情形
B9: 营业收入（一致预测） | C9: =IS!C4 -> 343360.83 | D9: =IS!D4 -> 345708.71 | E9: =IS!E4 -> 373709.8 | F9: =E9*(1+F10) -> 391948.95 | G9: =F9*(1+G10) -> 414028.02 | H9: =G9*(1+H10) -> 440828.11 | I9: =H9*(1+I10) -> 473455.12 | J9: =I9*(1+J10) -> 513300.75
B10: 营业收入同比（%） | D10: =IS!D4/IS!C4-1 -> 0.0068379378 | E10: =IS!E4/IS!D4-1 -> 0.080996195 | F10: =CHOOSE(Assumptions!$C$8,F11,F12,F13) -> 0.04880564 | G10: =CHOOSE(Assumptions!$C$8,G11,G12,G13) -> 0.056331497 | H10: =CHOOSE(Assumptions!$C$8,H11,H12,H13) -> 0.064730149 | I10: =CHOOSE(Assumptions!$C$8,I11,I12,I13) -> 0.074012993 | J10: =CHOOSE(Assumptions!$C$8,J11,J12,J13) -> 0.084159259
B11: 保守情形 | F11: =F12*0.9 -> 0.043925076 | G11: =G12*0.9 -> 0.050698347 | H11: =H12*0.9 -> 0.058257134 | I11: =I12*0.9 -> 0.066611693 | J11: =J12*0.9 -> 0.075743333 | L11: 相对基础情形90%
B12: 基本情形 | F12: =收入拆分!F5 -> 0.04880564 | G12: =收入拆分!G5 -> 0.056331497 | H12: =收入拆分!H5 -> 0.064730149 | I12: =收入拆分!I5 -> 0.074012993 | J12: =收入拆分!J5 -> 0.084159259
B13: 乐观情形 | F13: =F12*1.1 -> 0.053686205 | G13: =G12*1.1 -> 0.061964646 | H13: =H12*1.1 -> 0.071203164 | I13: =I12*1.1 -> 0.081414292 | J13: =J12*1.1 -> 0.092575185 | L13: 管理层预测的乐观情形
B14: 毛利率（%） | C14: =(IS!C4+IS!C5)/IS!C4 -> 0.22959762 | D14: =(IS!D4+IS!D5)/IS!D4 -> 0.24636351 | E14: =(IS!E4+IS!E5)/IS!E4 -> 0.26819856 | F14: =收入拆分!F7 -> 0.27753001 | G14: =收入拆分!G7 -> 0.27665013 | H14: =收入拆分!H7 -> 0.2759619 | I14: =收入拆分!I7 -> 0.27552585 | J14: =收入拆分!J7 -> 0.27540383 | L14: link收入拆分的数据
B15: 税金及附加/营业收入（%） | C15: =-IS!C6/IS!C$4 -> 0.0046871392 | D15: =-IS!D6/IS!D$4 -> 0.004529478 | E15: =-IS!E6/IS!E$4 -> 0.0048607235 | F15: =E15 -> 0.0048607235 | G15: =F15 -> 0.0048607235 | H15: =G15 -> 0.0048607235 | I15: =H15 -> 0.0048607235 | J15: =I15 -> 0.0048607235 | L15: 按上一年数据测算
B16: 销售费用率（%） | C16: =-IS!C7/IS!C$4 -> 0.083432173 | D16: =-IS!D7/IS!D$4 -> 0.083064497 | E16: =-IS!E7/IS!E$4 -> 0.093336808 | F16: =E16+0.001 -> 0.094336808 | G16: =F16+0.001 -> 0.095336808 | H16: =G16+0.001 -> 0.096336808 | I16: =H16+0.001 -> 0.097336808 | J16: =I16+0.001 -> 0.098336808 | L16: 波动不大，保守估计按上一年数
B17: 管理费用率（%） | C17: =-IS!C8/IS!C$4 -> 0.029899392 | D17: =-IS!D8/IS!D$4 -> 0.033504102 | E17: =-IS!E8/IS!E$4 -> 0.036062501 | F17: =E17-0.001 -> 0.035062501 | G17: =F17 -> 0.035062501 | H17: =G17 -> 0.035062501 | I17: =H17 -> 0.035062501 | J17: =I17 -> 0.035062501 | L17: 管理费用率呈现逐年上升趋势，按上一年数据测算
B18: 研发费用率（%） | C18: =-IS!C9/IS!C$4 -> 0.034992081 | D18: =-IS!D9/IS!D$4 -> 0.036500411 | E18: =-IS!E9/IS!E$4 -> 0.039023087 | F18: =E18 -> 0.039023087 | G18: =F18 -> 0.039023087 | H18: =G18 -> 0.039023087 | I18: =H18 -> 0.039023087 | J18: =I18 -> 0.039023087 | L18: 研发费用率呈现逐年上升趋势，按上一年数据测算
B19: 财务费用率（%） | C19: =-IS!C11/IS!C4 -> -0.012774055 | D19: =-IS!D11/IS!D4 -> -0.0097986828 | E19: =-IS!E11/IS!E4 -> -0.0087277882 | F19: =-IS!F11/IS!F4 -> 0.0023425308 | G19: =-IS!G11/IS!G4 -> 0.0016395199 | H19: =-IS!H11/IS!H4 -> 0.0010330315 | I19: =-IS!I11/IS!I4 -> 0.00044022609 | J19: =-IS!J11/IS!J4 -> -0.0001310108
B20: 所得税率（%） | C20: =-IS!C23/IS!C22 -> 0.13904497 | D20: =-IS!D23/IS!D22 -> 0.14696508 | E20: =-IS!E23/IS!E22 -> 0.16202984 | F20: =AVERAGE(E20) -> 0.16202984 | G20: =F20 -> 0.16202984 | H20: =G20 -> 0.16202984 | I20: =H20 -> 0.16202984 | J20: =I20 -> 0.16202984 | L20: 参考上年度实际所得税率
B21: EBIT/收入（%） | C21: =IS!C10/IS!C4 -> 0.076586837 | D21: =IS!D10/IS!D4 -> 0.088765018 | E21: =IS!E10/IS!E4 -> 0.09491544 | F21: =IS!F10/IS!F4 -> 0.10424689 | G21: =IS!G10/IS!G4 -> 0.10236701 | H21: =IS!H10/IS!H4 -> 0.10067878 | I21: =IS!I10/IS!I4 -> 0.099242728 | J21: =IS!J10/IS!J4 -> 0.098120713
B22: 净利率（%） | C22: =IS!C24/IS!C4 -> 0.084795491 | D22: =IS!D24/IS!D4 -> 0.086394641 | E22: =IS!E24/IS!E4 -> 0.090392545 | F22: =IS!F24/IS!F4 -> 0.089421605 | G22: =IS!G24/IS!G4 -> 0.088220578 | H22: =IS!H24/IS!H4 -> 0.087082242 | I22: =IS!I24/IS!I4 -> 0.08612878 | J22: =IS!J24/IS!J4 -> 0.085408342
B23: 分红率（%） | C23: =IS!C27/IS!C26 -> -0.40727189 | D23: =IS!D27/IS!D26 -> -0.5805004 | E23: =IS!E27/IS!E26 -> -0.61560958 | F23: =C23 -> -0.40727189 | G23: =F23 -> -0.40727189 | H23: =G23 -> -0.40727189 | I23: =H23 -> -0.40727189 | J23: =I23 -> -0.40727189 | L23: 呈现上升趋势，保守按照2023年数预计
B24: 少数股东损益占收入比（%） | C24: =IS!C25/IS!C4 -> 0.0012864892 | D24: =IS!D25/IS!D4 -> 0.00074259049 | E24: =IS!E25/IS!E4 -> 6.8020694e-05 | F24: =E24 -> 6.8020694e-05 | G24: =F24 -> 6.8020694e-05 | H24: =G24 -> 6.8020694e-05 | I24: =H24 -> 6.8020694e-05 | J24: =I24 -> 6.8020694e-05 | L24: 按上一年数据测算
B26: BS
B28: 所需现金/营业收入 | C28: =BS!C5/IS!C4 -> 0.20932953 | D28: =BS!D5/IS!D4 -> 0.15987477 | E28: =BS!E5/IS!E4 -> 0.21854886 | F28: =AVERAGE(C28:E28) -> 0.19591772 | G28: =F28 -> 0.19591772 | H28: =G28 -> 0.19591772 | I28: =H28 -> 0.19591772 | J28: =I28 -> 0.19591772 | L28: 采用三年平均数
B29: 应收款项（应收票据+应收账款） | C29: =BS!C8+BS!C9 -> 29421.35 | D29: =BS!D8+BS!D9 -> 32996.1 | E29: =BS!E8+BS!E9 -> 38406.7 | F29: =IFERROR(IS!F4/(365/F30),0) -> 40281.164 | G29: =IFERROR(IS!G4/(365/G30),0) -> 42550.262 | H29: =IFERROR(IS!H4/(365/H30),0) -> 45304.547 | I29: =IFERROR(IS!I4/(365/I30),0) -> 48657.672 | J29: =IFERROR(IS!J4/(365/J30),0) -> 52752.665
B30: 应收款项周转天数 | C30: =IFERROR(365/(IS!C4/C29),0) -> 31.275532 | D30: =IFERROR(365/(IS!D4/D29),0) -> 34.837353 | E30: =IFERROR(365/(IS!E4/E29),0) -> 37.511581 | F30: =E30 -> 37.511581 | G30: =F30 -> 37.511581 | H30: =G30 -> 37.511581 | I30: =H30 -> 37.511581 | J30: =I30 -> 37.511581 | L30: 假定未来保持这一水平
B31: 应收票据占比% | C31: =BS!C8/C$29 -> 0.16263394 | D31: =BS!D8/D$29 -> 0.1442028 | E31: =BS!E8/E$29 -> 0.14377596 | F31: =E31 -> 0.14377596 | G31: =F31 -> 0.14377596 | H31: =G31 -> 0.14377596 | I31: =H31 -> 0.14377596 | J31: =I31 -> 0.14377596
B32: 应收账款占比% | C32: =BS!C9/C$29 -> 0.83736606 | D32: =BS!D9/D$29 -> 0.8557972 | E32: =BS!E9/E$29 -> 0.85622404 | F32: =E32 -> 0.85622404 | G32: =F32 -> 0.85622404 | H32: =G32 -> 0.85622404 | I32: =H32 -> 0.85622404 | J32: =I32 -> 0.85622404
B33: 应收款项融资/应收款项比例% | C33: =BS!C10/C29 -> 0.3491869 | D33: =BS!D10/D29 -> 0.4099436 | E33: =BS!E10/E29 -> 0.34707512 | F33: =E33 -> 0.34707512 | G33: =F33 -> 0.34707512 | H33: =G33 -> 0.34707512 | I33: =H33 -> 0.34707512 | J33: =I33 -> 0.34707512
B34: 预付款项/营业成本比例% | C34: =-BS!C11/IS!C5 -> 0.016455131 | D34: =-BS!D11/IS!D5 -> 0.016762231 | E34: =-BS!E11/IS!E5 -> 0.012125835 | F34: =E34 -> 0.012125835 | G34: =F34 -> 0.012125835 | H34: =G34 -> 0.012125835 | I34: =H34 -> 0.012125835 | J34: =I34 -> 0.012125835 | L34: 按上一年度数据
B35: 存货周转天数 | C35: =IFERROR(365/(-IS!C5/BS!C13),0) -> 63.367762 | D35: =IFERROR(365/(-IS!D5/BS!D13),0) -> 64.506304 | E35: =IFERROR(365/(-IS!E5/BS!E13),0) -> 63.181013 | F35: =E35 -> 63.181013 | G35: =F35 -> 63.181013 | H35: =G35 -> 63.181013 | I35: =H35 -> 63.181013 | J35: =I35 -> 63.181013 | L35: 按上一年度数据
B36: 合同资产/营业收入比例% | C36: =BS!C14/IS!C4 -> 0.011135458 | D36: =BS!D14/IS!D4 -> 0.013013731 | E36: =BS!E14/IS!E4 -> 0.010826395 | F36: =E36 -> 0.010826395 | G36: =F36 -> 0.010826395 | H36: =G36 -> 0.010826395 | I36: =H36 -> 0.010826395 | J36: =I36 -> 0.010826395
B37: 应付款项（应付票据+应付账款） | C37: =BS!C53+BS!C54 -> 98735.57 | D37: =BS!D53+BS!D54 -> 89805.65 | E37: =BS!E53+BS!E54 -> 94238.08 | F37: =-IFERROR(IS!F5/(365/F38),0) -> 97577.12 | G37: =-IFERROR(IS!G5/(365/G38),0) -> 103199.32 | H37: =-IFERROR(IS!H5/(365/H38),0) -> 109983.97 | I37: =-IFERROR(IS!I5/(365/I38),0) -> 118195.35 | J37: =-IFERROR(IS!J5/(365/J38),0) -> 128164.17
B38: 应付账款周转天数 | C38: =IFERROR(365/(-IS!C5/C37),0) -> 136.23796 | D38: =IFERROR(365/(-IS!D5/D37),0) -> 125.81264 | E38: =IFERROR(365/(-IS!E5/E37),0) -> 125.7742 | F38: =E38 -> 125.7742 | G38: =F38 -> 125.7742 | H38: =G38 -> 125.7742 | I38: =H38 -> 125.7742 | J38: =I38 -> 125.7742 | L38: 假定未来保持这一水平
B39: 应付票据占比% | C39: =BS!C53/C$37 -> 0.3317144 | D39: =BS!D53/D$37 -> 0.28475291 | E39: =BS!E53/E$37 -> 0.2303486 | F39: =E39 -> 0.2303486 | G39: =F39 -> 0.2303486 | H39: =G39 -> 0.2303486 | I39: =H39 -> 0.2303486 | J39: =I39 -> 0.2303486
B40: 应付账款占比% | C40: =BS!C54/C$37 -> 0.6682856 | D40: =BS!D54/D$37 -> 0.71524709 | E40: =BS!E54/E$37 -> 0.7696514 | F40: =E40 -> 0.7696514 | G40: =F40 -> 0.7696514 | H40: =G40 -> 0.7696514 | I40: =H40 -> 0.7696514 | J40: =I40 -> 0.7696514
B41: 预收款项/营业收入（%） | C41: =BS!C55/IS!C4 -> 0 | D41: =BS!D55/IS!D4 -> 0 | E41: =BS!E55/IS!E4 -> 0 | F41: =E41 -> 0 | G41: =F41 -> 0 | H41: =G41 -> 0 | I41: =H41 -> 0 | J41: =I41 -> 0
B42: 合同负债/营业收入（%） | C42: =BS!C56/IS!C4 -> 0.069654422 | D42: =BS!D56/IS!D4 -> 0.080877453 | E42: =BS!E56/IS!E4 -> 0.11175912 | F42: =E42 -> 0.11175912 | G42: =F42 -> 0.11175912 | H42: =G42 -> 0.11175912 | I42: =H42 -> 0.11175912 | J42: =I42 -> 0.11175912 | L42: 按上一年度数据
B43: 应付职工薪酬/营业收入（%） | C43: =BS!C57/IS!C4 -> 0.02194534 | D43: =BS!D57/IS!D4 -> 0.020688573 | E43: =BS!E57/IS!E4 -> 0.024286305 | F43: =E43 -> 0.024286305 | G43: =F43 -> 0.024286305 | H43: =G43 -> 0.024286305 | I43: =H43 -> 0.024286305 | J43: =I43 -> 0.024286305 | L43: 按上年数
B45: 负债计算
B47: 短期借款
B48: 利率 | C48: 0.0335 | L48: 参考最新一年期贷款LPR
...

Sheet FCFF估值
B2: 单位：百万元 | C2: =Assumptions!C2 -> 2021 | D2: =Assumptions!D2 -> 2022 | E2: =Assumptions!E2 -> 2023 | F2: =Assumptions!F2 -> 2024 | G2: =Assumptions!G2 -> 2025 | H2: =Assumptions!H2 -> 2026 | I2: =Assumptions!I2 -> 2027 | J2: =Assumptions!J2 -> 2028 | K2: =J2+1 -> 2029 | L2: =K2+1 -> 2030 | M2: =L2+1 -> 2031 | N2: =M2+1 -> 2032 | O2: =N2+1 -> 2033 | P2: =O2+1 -> 2034 | Q2: =P2+1 -> 2035
B4: FCFF估值 | F4: 第一阶段 | K4: 第二阶段
B6: EBIT | F6: =IS!F10 -> 40859.457 | G6: =IS!G10 -> 42382.808 | H6: =IS!H10 -> 44382.035 | I6: =IS!I10 -> 46986.978 | J6: =IS!J10 -> 50365.436
B7: 调整的税 | F7: =-F6*Assumptions!F20 -> -6620.4512 | G7: =-G6*Assumptions!G20 -> -6867.2796 | H7: =-H6*Assumptions!H20 -> -7191.2139 | I7: =-I6*Assumptions!I20 -> -7613.2924 | J7: =-J6*Assumptions!J20 -> -8160.7034
B8: EBIAT | F8: =F6+F7 -> 34239.006 | G8: =G6+G7 -> 35515.529 | H8: =H6+H7 -> 37190.821 | I8: =I6+I7 -> 39373.685 | J8: =J6+J7 -> 42204.732
B10: 加：折旧摊销 | F10: =CF!F6 -> 209.30383 | G10: =CF!G6 -> 226.6201 | H10: =CF!H6 -> 245.05725 | I10: =CF!I6 -> 264.85898 | J10: =CF!J6 -> 286.32722
B11: 净营运资金的变化 | F11: =CF!F9 -> 4300.6199 | G11: =CF!G9 -> 2308.192 | H11: =CF!H9 -> 2783.3763 | I11: =CF!I9 -> 3366.1591 | J11: =CF!J9 -> 4083.4818
B13: 固定资产的购置 | F13: =CF!F33 -> -4912.2207 | G13: =CF!G33 -> -5188.9335 | H13: =CF!H33 -> -5188.9335 | I13: =CF!I33 -> -5188.9335 | J13: =CF!J33 -> -5188.9335
B14: 固定资产-非同一控制下企业合并付出的对价 | F14: =CF!F34 -> 0 | G14: =CF!G34 -> 0 | H14: =CF!H34 -> 0 | I14: =CF!I34 -> 0 | J14: =CF!J34 -> 0
B15: 在建工程的购置 | F15: =CF!F35 -> -300 | G15: =CF!G35 -> -300 | H15: =CF!H35 -> -168 | I15: =CF!I35 -> -10 | J15: =CF!J35 -> -10
B16: 生产性生物资产的变化 | F16: =CF!F36 -> 0 | G16: =CF!G36 -> 0 | H16: =CF!H36 -> 0 | I16: =CF!I36 -> 0 | J16: =CF!J36 -> 0
B17: 油气资产的变化 | F17: =CF!F37 -> 0 | G17: =CF!G37 -> 0 | H17: =CF!H37 -> 0 | I17: =CF!I37 -> 0 | J17: =CF!J37 -> 0
B18: 使用权资产的购置 | F18: =CF!F38 -> -2278.5565 | G18: =CF!G38 -> -2406.911 | H18: =CF!H38 -> -2562.7107 | I18: =CF!I38 -> -2752.3846 | J18: =CF!J38 -> -2984.0232
B19: 使用权资产-非同一控制下企业合并付出的对价 | F19: =CF!F39 -> 0 | G19: =CF!G39 -> 0 | H19: =CF!H39 -> 0 | I19: =CF!I39 -> 0 | J19: =CF!J39 -> 0
B20: 无形资产的购置 | F20: =CF!F40 -> -329.50222 | G20: =CF!G40 -> -348.06357 | H20: =CF!H40 -> -370.59378 | I20: =CF!I40 -> -398.02253 | J20: =CF!J40 -> -398.02253
B21: 无形资产-非同一控制下企业合并付出的对价 | F21: =CF!F41 -> 0 | G21: =CF!G41 -> 0 | H21: =CF!H41 -> 0 | I21: =CF!I41 -> 0 | J21: =CF!J41 -> 0
B22: 开发支出的购置 | F22: =CF!F42 -> 0 | G22: =CF!G42 -> 0 | H22: =CF!H42 -> 0 | I22: =CF!I42 -> 0 | J22: =CF!J42 -> 0
B23: 长期待摊费用的变化 | F23: =CF!F44 -> -163.92832 | G23: =CF!G44 -> -173.16265 | H23: =CF!H44 -> -184.37149 | I23: =CF!I44 -> -198.01738 | J23: =CF!J44 -> -214.68238
B25: FCFF | F25: =F8+SUM(F10:F11)+SUM(F13:F23) -> 30764.722 | G25: =G8+SUM(G10:G11)+SUM(G13:G23) -> 29633.27 | H25: =H8+SUM(H10:H11)+SUM(H13:H23) -> 31744.645 | I25: =I8+SUM(I10:I11)+SUM(I13:I23) -> 34457.345 | J25: =J8+SUM(J10:J11)+SUM(J13:J23) -> 37778.88 | K25: =J25*(1+K26) -> 40692.252 | L25: =K25*(1+L26) -> 43202.685 | M25: =L25*(1+M26) -> 45334.933 | N25: =M25*(1+N26) -> 47124.92 | O25: =N25*(1+O26) -> 48613.45 | P25: =O25*(1+P26) -> 49841.888 | Q25: =P25*(1+Q26) -> 50849.472
B26: 增长率（%） | G26: =G25/F25-1 -> -0.036777574 | H26: =H25/G25-1 -> 0.07125014 | I26: =I25/H25-1 -> 0.0854538 | J26: =J25/I25-1 -> 0.096395541 | K26: =J26*0.8 -> 0.077116433 | L26: =K26*0.8 -> 0.061693146 | M26: =L26*0.8 -> 0.049354517 | N26: =M26*0.8 -> 0.039483613 | O26: =N26*0.8 -> 0.031586891 | P26: =O26*0.8 -> 0.025269513 | Q26: =P26*0.8 -> 0.02021561
B28: WACC | C28: =C82 -> 0.080252681
B29: 估值日期 | C29: 45604
B31: 自由现金流折现
B32: 折现年份 | F32: =DATEDIF(C29,DATE(YEAR(C29),12,31),"d")/365/2 -> 0.07260274 | G32: =F32+1 -> 1.0726027 | H32: =G32+1 -> 2.0726027 | I32: =H32+1 -> 3.0726027 | J32: =I32+1 -> 4.0726027 | K32: =J32+1 -> 5.0726027 | L32: =K32+1 -> 6.0726027 | M32: =L32+1 -> 7.0726027 | N32: =M32+1 -> 8.0726027 | ... Q32: =P32+1 -> 11.072603
B33: 折现系数 | F33: =1/(1+$C$28)^F32 -> 0.99441111 | G33: =1/(1+$C$28)^G32 -> 0.92053565 | H33: =1/(1+$C$28)^H32 -> 0.85214846 | I33: =1/(1+$C$28)^I32 -> 0.78884179 | J33: =1/(1+$C$28)^J32 -> 0.73023821 | K33: =1/(1+$C$28)^K32 -> 0.67598834 | L33: =1/(1+$C$28)^L32 -> 0.62576872 | M33: =1/(1+$C$28)^M32 -> 0.57927995 | ... Q33: =1/(1+$C$28)^Q32 -> 0.42538981
B34: 现金流现值 | F34: =F25*F33 -> 30592.781 | G34: =G25*G33 -> 27278.482 | H34: =H25*H33 -> 27051.15 | I34: =I25*I33 -> 27181.394 | J34: =J25*J33 -> 27587.582 | K34: =K25*K33 -> 27507.488 | L34: =L25*L33 -> 27034.889 | M34: =M25*M33 -> 26261.618 | ... Q34: =Q25*Q33 -> 21630.847
B36: 永续增长率 | Q36: 0.02
B37: 预测期末企业价值 | Q37: =Q25*(1+Q36)/($C$28-Q36) -> 860815.82
B38: 折现年份 | Q38: =Q32+F32 -> 11.145205
B39: 折现系数 | Q39: =1/(1+$C$28)^Q38 -> 0.42301235
B40: 终值的现值 | Q40: =Q37*Q39 -> 364135.73
B42: 企业价值的现值 | F42: =SUM(F34:Q34)+AVERAGE(Q40) -> 678568.27
B44: 非核心资产账面价值 | F44: =SUM(BS!E6:E7,BS!E22:E27,BS!E29:E32)-SUM(BS!E51:E52) -> 22836.28 | H44: 投资性资产减投资性负债，用上年底数
B45: 非核心资产市场价值/账面价值 | F45: 1 | H45: 按公允价值计算
B46: 非核心资产市值价值 | F46: =F44*F45 -> 22836.28
B48: 现金 | F48: =BS!E5 -> 81673.85
B49: 有息债务账面值 | F49: =BS!E49+BS!E50+BS!E60+BS!E61+BS!E66+BS!E67+BS!E68 -> 74769.88
B51: 少数股东权益账面价值 | F51: =BS!E88 -> 11420.82
B52: 少数股东权益市场价值/账面价值 | F52: 3.2212 | H52: 该公司目前的市净率
B53: 少数股东权益市场价值 | F53: =F51*F52 -> 36788.745
...

Sheet 可比公司估值
G3: 1.3833 | H3: 14.7381 | I3: 3.2212 | J3: 1.1688 | K3: 14.9008
B4: 证券代码 | C4: 证券名称 | D4: 总市值（百万元） | E4: 2022年3季度收入（百万元） | F4: 2022年3季度净利润（百万元） | G4: 市销率（TTM） | H4: 市盈率（TTM） | I4: 市净率（最新） | J4: PEG值（LYR） | K4: EV/EBITDA倍数
B5: 000651.SZ | C5: 格力电器 | D5: 247862.2 | E5: 146722.38 | F5: 21214.823 | G5: 1.2606 | H5: 8.025 | I5: 2.0395 | J5: 0.4641 | K5: 9.7416
B6: 002050.SZ | C6: 三花智控 | D6: 93608.33 | E6: 20562.897 | F6: 2319.5232 | G6: 3.5804 | H6: 30.5577 | I6: 5.1294 | J6: 2.3721 | K6: 22.1851
B7: 002668.SZ | C7: TCL智家 | D7: 12142.048 | E7: 13945.388 | F7: 1573.6912 | G7: 0.6828 | H7: 12.4555 | I7: 7.4603 | J7: 0.1802 | K7: 7.0232
B8: 000521.SZ | C8: 长虹美菱 | D8: 8952.7903 | E8: 22757.7 | F8: 543.2789 | G8: 0.3493 | H8: 12.5824 | I8: 1.6256 | J8: 0.0646 | K8: 10.5317
B9: 000921.SZ | C9: 海信家电 | D9: 40341.525 | E9: 70579.088 | F9: 4167.2224 | G9: 0.4798 | H9: 13.6684 | I9: 3.0612 | J9: 0.1579 | K9: 6.7161
B10: 600690.SH | C10: 海尔智家 | D10: 255718.77 | E10: 202971.2 | F10: 15436.313 | G10: 1.0292 | H10: 14.7015 | I10: 2.5494 | J10: 1.2857 | K10: 10.9233
C12: 最大值 | D12: =MAX(D5:D11) -> 255718.77 | E12: =MAX(E5:E11) -> 202971.2 | F12: =MAX(F5:F11) -> 21214.823 | G12: =MAX(G5:G11) -> 3.5804 | H12: =MAX(H5:H11) -> 30.5577 | I12: =MAX(I5:I11) -> 7.4603 | J12: =MAX(J5:J11) -> 2.3721 | K12: =MAX(K5:K11) -> 22.1851
C13: 最小值 | D13: =MIN(D5:D11) -> 8952.7903 | E13: =MIN(E5:E11) -> 13945.388 | F13: =MIN(F5:F11) -> 543.2789 | G13: =MIN(G5:G11) -> 0.3493 | H13: =MIN(H5:H11) -> 8.025 | I13: =MIN(I5:I11) -> 1.6256 | J13: =MIN(J5:J11) -> 0.0646 | K13: =MIN(K5:K11) -> 6.7161
C14: 平均值 | D14: =AVERAGE(D5:D11) -> 109770.95 | E14: =AVERAGE(E5:E11) -> 79589.775 | F14: =AVERAGE(F5:F11) -> 7542.4753 | G14: =AVERAGE(G5:G11) -> 1.23035 | H14: =AVERAGE(H5:H11) -> 15.33175 | I14: =AVERAGE(I5:I11) -> 3.6442333 | J14: =AVERAGE(J5:J11) -> 0.7541 | K14: =AVERAGE(K5:K11) -> 11.186833
C15: 中位数 | D15: =MEDIAN(D5:D11) -> 66974.927 | E15: =MEDIAN(E5:E11) -> 46668.394 | F15: =MEDIAN(F5:F11) -> 3243.3728 | G15: =MEDIAN(G5:G11) -> 0.856 | H15: =MEDIAN(H5:H11) -> 13.1254 | I15: =MEDIAN(I5:I11) -> 2.8053 | J15: =MEDIAN(J5:J11) -> 0.32215 | K15: =MEDIAN(K5:K11) -> 10.13665
B17: 标的公司指标 | D17: 总市值（百万元） | E17: 股份总数（百万股） | F17: 最新股价（元） | G17: 2023年收入（百万元） | H17: 2023年归母净利润（百万元） | I17: 2022年归母净资产（百万元） | J17: 净利润上年同比增长率(%) | K17: EBITDA（百万元）
